Workbook
Name _Loc1: [3]Request!$M$125
Name _Loc10: [4]Request!$M$134
Name _Loc11: [4]Request!$M$135
Name _Loc12: [4]Request!$M$136
Name _Loc13: [4]Request!$M$137
Name _Loc14: [4]Request!$M$138
Name _Loc15: [4]Request!$M$139
Name _Loc16: [4]Request!$M$140
Name _Loc17: [4]Request!$M$141
Name _Loc18: [4]Request!$M$142
Name _Loc19: [4]Request!$M$143
Name _Loc2: [4]Request!$M$126
Name _Loc20: [4]Request!$M$144
Name _Loc21: [4]Request!$M$145
Name _Loc22: [4]Request!$M$146
Name _Loc23: [4]Request!$M$147
Name _Loc24: [4]Request!$M$148
Name _Loc25: [4]Request!$M$149
Name _Loc26: [4]Request!$M$150
Name _Loc3: [4]Request!$M$127
Name _Loc4: [4]Request!$M$128
Name _Loc5: [4]Request!$M$129
Name _Loc6: [4]Request!$M$130
Name _Loc7: [4]Request!$M$131
Name _Loc8: [4]Request!$M$132
Name _Loc9: [4]Request!$M$133
Name Account: [4]Request!$B$17
Name Acct_number: [5]Summary!$E$2
Name AFD: #REF!
Name Agent: [4]Request!$A$60
Name Agent_Comm: [4]Request!$E$64
Name Agent_Delivery: [4]Request!$O$62
Name Agent_Involved: [4]Request!$P$62
Name Agent_Pickup: [4]Request!$N$62
Name Agent_Services: [4]Request!$E$66
Name AgentQ: [4]Request!$L$62
Name Alph_countries: [7]zones_input!$A$2:$A$214
Name anakg: '[4]Shipments - kg current'!$D$1
Name analb: '[4]Shipments - lb current'!$D$1
Name ApDsctKgADNR: #REF!
Name ApDsctKgComm: #REF!
Name ApDsctKgH1: #REF!
Name ApDsctKgH2: #REF!
Name ApDsctKgIEAppCurDisct: #REF!
Name ApDsctKgIEAppMin: #REF!
Name ApDsctKgIEReqCurDisct: #REF!
Name ApDsctKgIEReqMin: #REF!
Name ApDsctKgIERestore: #REF!
Name ApDsctKgIPAppCurDisct: #REF!
Name ApDsctKgIPAppMin: #REF!
Name ApDsctKgIPReqCurDisct: #REF!
Name ApDsctKgIPReqMin: #REF!
Name ApDsctKgIPRestore: #REF!
Name ApDsctKgLR: #REF!
Name ApDsctKgLR1: #REF!
Name ApDsctKgQ1: #REF!
Name ApDsctKgQ10: #REF!
Name ApDsctKgQ2: #REF!
Name ApDsctKgQ3: #REF!
Name ApDsctKgQ4: #REF!

Sheet Detailed Calculation table
A1: 产品编码 (Product Original RMB Cost) | B1: G00701-JA | C1: 利润（Profit） | F1: 0.07 | G1: 计算数量Quantity | L1: 1 | M1: 2 | N1: 3 | O1: 本期安全汇率 (Current safe exchange rate) | P1: 7.1 | Q1: Shipping Category运费参考表 | R1: 顺邮宝挂号
A3: 国家/地区Country | B3: 缩写Country abbreviation | C3: 1PCS美元总报价 (USD Quoation Price) | D3: 2PCS美元总报价 (USD Quoation Price) | E3: 3PCS美元总报价 (USD Quoation Price) | F3: 1PCS总运费(USD) (Total Freight) | G3: 2PCS总运费(USD) (Total Freight) | H3: 3PCS总运费(USD) (Total Freight) | I3: 1PCS产品成本（美金）(Product Original Cost USD) | J3: 2PCS产品成本（美金）(Product Original Cost USD) | K3: 3PCS产品成本（美金）(Product Original Cost USD) | L3: 1pcs产品总重量 (Total Product Weight) (KG) | M3: 2pcs产品总重量 (Total Product Weight) (KG) | N3: 3pcs产品总重量 (Total Product Weight) (KG) | O3: 1PCS总运费(RMB)(Total Freight) | P3: 2PCS总运费(RMB)(Total Freight) | Q3: 3PCS总运费(RMB)(Total Freight)
A4: 美国 | B4: US | C4: =(F4+I4)*(1+$F$1) -> 10.541761 | D4: =(G4+J4)*(1+$F$1) -> 15.055352 | E4: =(H4+K4)*(1+$F$1) -> 19.568944 | F4: =O4/$P$1 -> 7.8802817 | G4: =P4/$P$1 -> 10.126761 | H4: =Q4/$P$1 -> 12.373239 | I4: =(VLOOKUP($B$1,'Product Procurement Sheet'!B:I,8,0)*$L$1)/$P$1 -> 1.971831 | J4: =(VLOOKUP($B$1,'Product Procurement Sheet'!B:I,8,0)*$M$1)/$P$1 -> 3.943662 | K4: =(VLOOKUP($B$1,'Product Procurement Sheet'!B:I,8,0)*$N$1)/$P$1 -> 5.915493 | L4: =VLOOKUP($B$1,'Product Procurement Sheet'!B:D,3,FALSE)*$L$1 -> 0.11 | M4: =VLOOKUP($B$1,'Product Procurement Sheet'!B:D,3,FALSE)*$M$1 -> 0.22 | N4: =VLOOKUP($B$1,'Product Procurement Sheet'!B:D,3,FALSE)*$N$1 -> 0.33 | O4: {=(_xlfn.SINGLE(_xlfn.XLOOKUP(1,(INDIRECT($R$1&"!$C:$C")=B4)*(INDIRECT($R$1&"!$G:$G")<L4)*(INDIRECT($R$1&"!$H:$H")>=L4),INDIRECT($R$1&"!$K:$K"))))*L4+(_xlfn.SINGLE(_xlfn.XLOOKUP(1,(INDIRECT($R$1&"!$C:$C")=B4)*(INDIRECT($R$1&"!$G:$G")<L4)*(INDIRECT($R$1&"!$H:$H")>=L4),INDIRECT($R$1&"!$L:$L"))))} -> 55.95 | P4: {=(_xlfn.SINGLE(_xlfn.XLOOKUP(1,(INDIRECT($R$1&"!$C:$C")=B4)*(INDIRECT($R$1&"!$G:$G")<M4)*(INDIRECT($R$1&"!$H:$H")>=M4),INDIRECT($R$1&"!$K:$K"))))*M4+(_xlfn.SINGLE(_xlfn.XLOOKUP(1,(INDIRECT($R$1&"!$C:$C")=B4)*(INDIRECT($R$1&"!$G:$G")<M4)*(INDIRECT($R$1&"!$H:$H")>=M4),INDIRECT($R$1&"!$L:$L"))))} -> 71.9 | Q4: {=(_xlfn.SINGLE(_xlfn.XLOOKUP(1,(INDIRECT($R$1&"!$C:$C")=B4)*(INDIRECT($R$1&"!$G:$G")<N4)*(INDIRECT($R$1&"!$H:$H")>=N4),INDIRECT($R$1&"!$K:$K"))))*N4+(_xlfn.SINGLE(_xlfn.XLOOKUP(1,(INDIRECT($R$1&"!$C:$C")=B4)*(INDIRECT($R$1&"!$G:$G")<N4)*(INDIRECT($R$1&"!$H:$H")>=N4),INDIRECT($R$1&"!$L:$L"))))} -> 87.85
A5: 英国 | B5: UK/GB | C5: =(F5+I5)*(1+$F$1) -> #N/A | D5: =(G5+J5)*(1+$F$1) -> #N/A | E5: =(H5+K5)*(1+$F$1) -> #N/A | F5: =O5/$P$1 -> #N/A | G5: =P5/$P$1 -> #N/A | H5: =Q5/$P$1 -> #N/A | I5: =(VLOOKUP($B$1,'Product Procurement Sheet'!B:I,8,0)*$L$1)/$P$1 -> 1.971831 | J5: =(VLOOKUP($B$1,'Product Procurement Sheet'!B:I,8,0)*$M$1)/$P$1 -> 3.943662 | K5: =(VLOOKUP($B$1,'Product Procurement Sheet'!B:I,8,0)*$N$1)/$P$1 -> 5.915493 | L5: =VLOOKUP($B$1,'Product Procurement Sheet'!B:D,3,FALSE)*$L$1 -> 0.11 | M5: =VLOOKUP($B$1,'Product Procurement Sheet'!B:D,3,FALSE)*$M$1 -> 0.22 | N5: =VLOOKUP($B$1,'Product Procurement Sheet'!B:D,3,FALSE)*$N$1 -> 0.33 | O5: {=(_xlfn.SINGLE(_xlfn.XLOOKUP(1,(INDIRECT($R$1&"!$C:$C")=B5)*(INDIRECT($R$1&"!$G:$G")<L5)*(INDIRECT($R$1&"!$H:$H")>=L5),INDIRECT($R$1&"!$K:$K"))))*L5+(_xlfn.SINGLE(_xlfn.XLOOKUP(1,(INDIRECT($R$1&"!$C:$C")=B5)*(INDIRECT($R$1&"!$G:$G")<L5)*(INDIRECT($R$1&"!$H:$H")>=L5),INDIRECT($R$1&"!$L:$L"))))} -> #N/A | P5: {=(_xlfn.SINGLE(_xlfn.XLOOKUP(1,(INDIRECT($R$1&"!$C:$C")=B5)*(INDIRECT($R$1&"!$G:$G")<M5)*(INDIRECT($R$1&"!$H:$H")>=M5),INDIRECT($R$1&"!$K:$K"))))*M5+(_xlfn.SINGLE(_xlfn.XLOOKUP(1,(INDIRECT($R$1&"!$C:$C")=B5)*(INDIRECT($R$1&"!$G:$G")<M5)*(INDIRECT($R$1&"!$H:$H")>=M5),INDIRECT($R$1&"!$L:$L"))))} -> #N/A | Q5: {=(_xlfn.SINGLE(_xlfn.XLOOKUP(1,(INDIRECT($R$1&"!$C:$C")=B5)*(INDIRECT($R$1&"!$G:$G")<N5)*(INDIRECT($R$1&"!$H:$H")>=N5),INDIRECT($R$1&"!$K:$K"))))*N5+(_xlfn.SINGLE(_xlfn.XLOOKUP(1,(INDIRECT($R$1&"!$C:$C")=B5)*(INDIRECT($R$1&"!$G:$G")<N5)*(INDIRECT($R$1&"!$H:$H")>=N5),INDIRECT($R$1&"!$L:$L"))))} -> #N/A
A6: 法国 | B6: FR | C6: =(F6+I6)*(1+$F$1) -> 6.3823239 | D6: =(G6+J6)*(1+$F$1) -> 9.9012676 | E6: =(H6+K6)*(1+$F$1) -> 13.420211 | F6: =O6/$P$1 -> 3.9929577 | G6: =P6/$P$1 -> 5.3098592 | H6: =Q6/$P$1 -> 6.6267606 | I6: =(VLOOKUP($B$1,'Product Procurement Sheet'!B:I,8,0)*$L$1)/$P$1 -> 1.971831 | J6: =(VLOOKUP($B$1,'Product Procurement Sheet'!B:I,8,0)*$M$1)/$P$1 -> 3.943662 | K6: =(VLOOKUP($B$1,'Product Procurement Sheet'!B:I,8,0)*$N$1)/$P$1 -> 5.915493 | L6: =VLOOKUP($B$1,'Product Procurement Sheet'!B:D,3,FALSE)*$L$1 -> 0.11 | M6: =VLOOKUP($B$1,'Product Procurement Sheet'!B:D,3,FALSE)*$M$1 -> 0.22 | N6: =VLOOKUP($B$1,'Product Procurement Sheet'!B:D,3,FALSE)*$N$1 -> 0.33 | O6: {=(_xlfn.SINGLE(_xlfn.XLOOKUP(1,(INDIRECT($R$1&"!$C:$C")=B6)*(INDIRECT($R$1&"!$G:$G")<L6)*(INDIRECT($R$1&"!$H:$H")>=L6),INDIRECT($R$1&"!$K:$K"))))*L6+(_xlfn.SINGLE(_xlfn.XLOOKUP(1,(INDIRECT($R$1&"!$C:$C")=B6)*(INDIRECT($R$1&"!$G:$G")<L6)*(INDIRECT($R$1&"!$H:$H")>=L6),INDIRECT($R$1&"!$L:$L"))))} -> 28.35 | P6: {=(_xlfn.SINGLE(_xlfn.XLOOKUP(1,(INDIRECT($R$1&"!$C:$C")=B6)*(INDIRECT($R$1&"!$G:$G")<M6)*(INDIRECT($R$1&"!$H:$H")>=M6),INDIRECT($R$1&"!$K:$K"))))*M6+(_xlfn.SINGLE(_xlfn.XLOOKUP(1,(INDIRECT($R$1&"!$C:$C")=B6)*(INDIRECT($R$1&"!$G:$G")<M6)*(INDIRECT($R$1&"!$H:$H")>=M6),INDIRECT($R$1&"!$L:$L"))))} -> 37.7 | Q6: {=(_xlfn.SINGLE(_xlfn.XLOOKUP(1,(INDIRECT($R$1&"!$C:$C")=B6)*(INDIRECT($R$1&"!$G:$G")<N6)*(INDIRECT($R$1&"!$H:$H")>=N6),INDIRECT($R$1&"!$K:$K"))))*N6+(_xlfn.SINGLE(_xlfn.XLOOKUP(1,(INDIRECT($R$1&"!$C:$C")=B6)*(INDIRECT($R$1&"!$G:$G")<N6)*(INDIRECT($R$1&"!$H:$H")>=N6),INDIRECT($R$1&"!$L:$L"))))} -> 47.05
A7: 奥地利 | B7: AT | C7: =(F7+I7)*(1+$F$1) -> 7.5728873 | D7: =(G7+J7)*(1+$F$1) -> 10.926056 | E7: =(H7+K7)*(1+$F$1) -> 14.279225 | F7: =O7/$P$1 -> 5.1056338 | G7: =P7/$P$1 -> 6.2676056 | H7: =Q7/$P$1 -> 7.4295775 | I7: =(VLOOKUP($B$1,'Product Procurement Sheet'!B:I,8,0)*$L$1)/$P$1 -> 1.971831 | J7: =(VLOOKUP($B$1,'Product Procurement Sheet'!B:I,8,0)*$M$1)/$P$1 -> 3.943662 | K7: =(VLOOKUP($B$1,'Product Procurement Sheet'!B:I,8,0)*$N$1)/$P$1 -> 5.915493 | L7: =VLOOKUP($B$1,'Product Procurement Sheet'!B:D,3,FALSE)*$L$1 -> 0.11 | M7: =VLOOKUP($B$1,'Product Procurement Sheet'!B:D,3,FALSE)*$M$1 -> 0.22 | N7: =VLOOKUP($B$1,'Product Procurement Sheet'!B:D,3,FALSE)*$N$1 -> 0.33 | O7: {=(_xlfn.SINGLE(_xlfn.XLOOKUP(1,(INDIRECT($R$1&"!$C:$C")=B7)*(INDIRECT($R$1&"!$G:$G")<L7)*(INDIRECT($R$1&"!$H:$H")>=L7),INDIRECT($R$1&"!$K:$K"))))*L7+(_xlfn.SINGLE(_xlfn.XLOOKUP(1,(INDIRECT($R$1&"!$C:$C")=B7)*(INDIRECT($R$1&"!$G:$G")<L7)*(INDIRECT($R$1&"!$H:$H")>=L7),INDIRECT($R$1&"!$L:$L"))))} -> 36.25 | P7: {=(_xlfn.SINGLE(_xlfn.XLOOKUP(1,(INDIRECT($R$1&"!$C:$C")=B7)*(INDIRECT($R$1&"!$G:$G")<M7)*(INDIRECT($R$1&"!$H:$H")>=M7),INDIRECT($R$1&"!$K:$K"))))*M7+(_xlfn.SINGLE(_xlfn.XLOOKUP(1,(INDIRECT($R$1&"!$C:$C")=B7)*(INDIRECT($R$1&"!$G:$G")<M7)*(INDIRECT($R$1&"!$H:$H")>=M7),INDIRECT($R$1&"!$L:$L"))))} -> 44.5 | Q7: {=(_xlfn.SINGLE(_xlfn.XLOOKUP(1,(INDIRECT($R$1&"!$C:$C")=B7)*(INDIRECT($R$1&"!$G:$G")<N7)*(INDIRECT($R$1&"!$H:$H")>=N7),INDIRECT($R$1&"!$K:$K"))))*N7+(_xlfn.SINGLE(_xlfn.XLOOKUP(1,(INDIRECT($R$1&"!$C:$C")=B7)*(INDIRECT($R$1&"!$G:$G")<N7)*(INDIRECT($R$1&"!$H:$H")>=N7),INDIRECT($R$1&"!$L:$L"))))} -> 52.75
A8: 意大利 | B8: IT | C8: =(F8+I8)*(1+$F$1) -> 7.1057042 | D8: =(G8+J8)*(1+$F$1) -> 10.293099 | E8: =(H8+K8)*(1+$F$1) -> 13.480493 | F8: =O8/$P$1 -> 4.6690141 | G8: =P8/$P$1 -> 5.6760563 | H8: =Q8/$P$1 -> 6.6830986 | I8: =(VLOOKUP($B$1,'Product Procurement Sheet'!B:I,8,0)*$L$1)/$P$1 -> 1.971831 | J8: =(VLOOKUP($B$1,'Product Procurement Sheet'!B:I,8,0)*$M$1)/$P$1 -> 3.943662 | K8: =(VLOOKUP($B$1,'Product Procurement Sheet'!B:I,8,0)*$N$1)/$P$1 -> 5.915493 | L8: =VLOOKUP($B$1,'Product Procurement Sheet'!B:D,3,FALSE)*$L$1 -> 0.11 | M8: =VLOOKUP($B$1,'Product Procurement Sheet'!B:D,3,FALSE)*$M$1 -> 0.22 | N8: =VLOOKUP($B$1,'Product Procurement Sheet'!B:D,3,FALSE)*$N$1 -> 0.33 | O8: {=(_xlfn.SINGLE(_xlfn.XLOOKUP(1,(INDIRECT($R$1&"!$C:$C")=B8)*(INDIRECT($R$1&"!$G:$G")<L8)*(INDIRECT($R$1&"!$H:$H")>=L8),INDIRECT($R$1&"!$K:$K"))))*L8+(_xlfn.SINGLE(_xlfn.XLOOKUP(1,(INDIRECT($R$1&"!$C:$C")=B8)*(INDIRECT($R$1&"!$G:$G")<L8)*(INDIRECT($R$1&"!$H:$H")>=L8),INDIRECT($R$1&"!$L:$L"))))} -> 33.15 | P8: {=(_xlfn.SINGLE(_xlfn.XLOOKUP(1,(INDIRECT($R$1&"!$C:$C")=B8)*(INDIRECT($R$1&"!$G:$G")<M8)*(INDIRECT($R$1&"!$H:$H")>=M8),INDIRECT($R$1&"!$K:$K"))))*M8+(_xlfn.SINGLE(_xlfn.XLOOKUP(1,(INDIRECT($R$1&"!$C:$C")=B8)*(INDIRECT($R$1&"!$G:$G")<M8)*(INDIRECT($R$1&"!$H:$H")>=M8),INDIRECT($R$1&"!$L:$L"))))} -> 40.3 | Q8: {=(_xlfn.SINGLE(_xlfn.XLOOKUP(1,(INDIRECT($R$1&"!$C:$C")=B8)*(INDIRECT($R$1&"!$G:$G")<N8)*(INDIRECT($R$1&"!$H:$H")>=N8),INDIRECT($R$1&"!$K:$K"))))*N8+(_xlfn.SINGLE(_xlfn.XLOOKUP(1,(INDIRECT($R$1&"!$C:$C")=B8)*(INDIRECT($R$1&"!$G:$G")<N8)*(INDIRECT($R$1&"!$H:$H")>=N8),INDIRECT($R$1&"!$L:$L"))))} -> 47.45
A9: 西班牙 | B9: ES | C9: =(F9+I9)*(1+$F$1) -> 5.9000704 | D9: =(G9+J9)*(1+$F$1) -> 9.0874648 | E9: =(H9+K9)*(1+$F$1) -> 12.274859 | F9: =O9/$P$1 -> 3.5422535 | G9: =P9/$P$1 -> 4.5492958 | H9: =Q9/$P$1 -> 5.556338 | I9: =(VLOOKUP($B$1,'Product Procurement Sheet'!B:I,8,0)*$L$1)/$P$1 -> 1.971831 | J9: =(VLOOKUP($B$1,'Product Procurement Sheet'!B:I,8,0)*$M$1)/$P$1 -> 3.943662 | K9: =(VLOOKUP($B$1,'Product Procurement Sheet'!B:I,8,0)*$N$1)/$P$1 -> 5.915493 | L9: =VLOOKUP($B$1,'Product Procurement Sheet'!B:D,3,FALSE)*$L$1 -> 0.11 | M9: =VLOOKUP($B$1,'Product Procurement Sheet'!B:D,3,FALSE)*$M$1 -> 0.22 | N9: =VLOOKUP($B$1,'Product Procurement Sheet'!B:D,3,FALSE)*$N$1 -> 0.33 | O9: {=(_xlfn.SINGLE(_xlfn.XLOOKUP(1,(INDIRECT($R$1&"!$C:$C")=B9)*(INDIRECT($R$1&"!$G:$G")<L9)*(INDIRECT($R$1&"!$H:$H")>=L9),INDIRECT($R$1&"!$K:$K"))))*L9+(_xlfn.SINGLE(_xlfn.XLOOKUP(1,(INDIRECT($R$1&"!$C:$C")=B9)*(INDIRECT($R$1&"!$G:$G")<L9)*(INDIRECT($R$1&"!$H:$H")>=L9),INDIRECT($R$1&"!$L:$L"))))} -> 25.15 | P9: {=(_xlfn.SINGLE(_xlfn.XLOOKUP(1,(INDIRECT($R$1&"!$C:$C")=B9)*(INDIRECT($R$1&"!$G:$G")<M9)*(INDIRECT($R$1&"!$H:$H")>=M9),INDIRECT($R$1&"!$K:$K"))))*M9+(_xlfn.SINGLE(_xlfn.XLOOKUP(1,(INDIRECT($R$1&"!$C:$C")=B9)*(INDIRECT($R$1&"!$G:$G")<M9)*(INDIRECT($R$1&"!$H:$H")>=M9),INDIRECT($R$1&"!$L:$L"))))} -> 32.3 | Q9: {=(_xlfn.SINGLE(_xlfn.XLOOKUP(1,(INDIRECT($R$1&"!$C:$C")=B9)*(INDIRECT($R$1&"!$G:$G")<N9)*(INDIRECT($R$1&"!$H:$H")>=N9),INDIRECT($R$1&"!$K:$K"))))*N9+(_xlfn.SINGLE(_xlfn.XLOOKUP(1,(INDIRECT($R$1&"!$C:$C")=B9)*(INDIRECT($R$1&"!$G:$G")<N9)*(INDIRECT($R$1&"!$H:$H")>=N9),INDIRECT($R$1&"!$L:$L"))))} -> 39.45
A10: 比利时 | B10: BE | C10: =(F10+I10)*(1+$F$1) -> 7.0152817 | D10: =(G10+J10)*(1+$F$1) -> 10.865775 | E10: =(H10+K10)*(1+$F$1) -> 14.716268 | F10: =O10/$P$1 -> 4.584507 | G10: =P10/$P$1 -> 6.2112676 | H10: =Q10/$P$1 -> 7.8380282 | I10: =(VLOOKUP($B$1,'Product Procurement Sheet'!B:I,8,0)*$L$1)/$P$1 -> 1.971831 | J10: =(VLOOKUP($B$1,'Product Procurement Sheet'!B:I,8,0)*$M$1)/$P$1 -> 3.943662 | K10: =(VLOOKUP($B$1,'Product Procurement Sheet'!B:I,8,0)*$N$1)/$P$1 -> 5.915493 | L10: =VLOOKUP($B$1,'Product Procurement Sheet'!B:D,3,FALSE)*$L$1 -> 0.11 | M10: =VLOOKUP($B$1,'Product Procurement Sheet'!B:D,3,FALSE)*$M$1 -> 0.22 | N10: =VLOOKUP($B$1,'Product Procurement Sheet'!B:D,3,FALSE)*$N$1 -> 0.33 | O10: {=(_xlfn.SINGLE(_xlfn.XLOOKUP(1,(INDIRECT($R$1&"!$C:$C")=B10)*(INDIRECT($R$1&"!$G:$G")<L10)*(INDIRECT($R$1&"!$H:$H")>=L10),INDIRECT($R$1&"!$K:$K"))))*L10+(_xlfn.SINGLE(_xlfn.XLOOKUP(1,(INDIRECT($R$1&"!$C:$C")=B10)*(INDIRECT($R$1&"!$G:$G")<L10)*(INDIRECT($R$1&"!$H:$H")>=L10),INDIRECT($R$1&"!$L:$L"))))} -> 32.55 | P10: {=(_xlfn.SINGLE(_xlfn.XLOOKUP(1,(INDIRECT($R$1&"!$C:$C")=B10)*(INDIRECT($R$1&"!$G:$G")<M10)*(INDIRECT($R$1&"!$H:$H")>=M10),INDIRECT($R$1&"!$K:$K"))))*M10+(_xlfn.SINGLE(_xlfn.XLOOKUP(1,(INDIRECT($R$1&"!$C:$C")=B10)*(INDIRECT($R$1&"!$G:$G")<M10)*(INDIRECT($R$1&"!$H:$H")>=M10),INDIRECT($R$1&"!$L:$L"))))} -> 44.1 | Q10: {=(_xlfn.SINGLE(_xlfn.XLOOKUP(1,(INDIRECT($R$1&"!$C:$C")=B10)*(INDIRECT($R$1&"!$G:$G")<N10)*(INDIRECT($R$1&"!$H:$H")>=N10),INDIRECT($R$1&"!$K:$K"))))*N10+(_xlfn.SINGLE(_xlfn.XLOOKUP(1,(INDIRECT($R$1&"!$C:$C")=B10)*(INDIRECT($R$1&"!$G:$G")<N10)*(INDIRECT($R$1&"!$H:$H")>=N10),INDIRECT($R$1&"!$L:$L"))))} -> 55.65
A11: 瑞士 | B11: CH | C11: =(F11+I11)*(1+$F$1) -> 7.1057042 | D11: =(G11+J11)*(1+$F$1) -> 10.293099 | E11: =(H11+K11)*(1+$F$1) -> 13.480493 | F11: =O11/$P$1 -> 4.6690141 | G11: =P11/$P$1 -> 5.6760563 | H11: =Q11/$P$1 -> 6.6830986 | I11: =(VLOOKUP($B$1,'Product Procurement Sheet'!B:I,8,0)*$L$1)/$P$1 -> 1.971831 | J11: =(VLOOKUP($B$1,'Product Procurement Sheet'!B:I,8,0)*$M$1)/$P$1 -> 3.943662 | K11: =(VLOOKUP($B$1,'Product Procurement Sheet'!B:I,8,0)*$N$1)/$P$1 -> 5.915493 | L11: =VLOOKUP($B$1,'Product Procurement Sheet'!B:D,3,FALSE)*$L$1 -> 0.11 | M11: =VLOOKUP($B$1,'Product Procurement Sheet'!B:D,3,FALSE)*$M$1 -> 0.22 | N11: =VLOOKUP($B$1,'Product Procurement Sheet'!B:D,3,FALSE)*$N$1 -> 0.33 | O11: {=(_xlfn.SINGLE(_xlfn.XLOOKUP(1,(INDIRECT($R$1&"!$C:$C")=B11)*(INDIRECT($R$1&"!$G:$G")<L11)*(INDIRECT($R$1&"!$H:$H")>=L11),INDIRECT($R$1&"!$K:$K"))))*L11+(_xlfn.SINGLE(_xlfn.XLOOKUP(1,(INDIRECT($R$1&"!$C:$C")=B11)*(INDIRECT($R$1&"!$G:$G")<L11)*(INDIRECT($R$1&"!$H:$H")>=L11),INDIRECT($R$1&"!$L:$L"))))} -> 33.15 | P11: {=(_xlfn.SINGLE(_xlfn.XLOOKUP(1,(INDIRECT($R$1&"!$C:$C")=B11)*(INDIRECT($R$1&"!$G:$G")<M11)*(INDIRECT($R$1&"!$H:$H")>=M11),INDIRECT($R$1&"!$K:$K"))))*M11+(_xlfn.SINGLE(_xlfn.XLOOKUP(1,(INDIRECT($R$1&"!$C:$C")=B11)*(INDIRECT($R$1&"!$G:$G")<M11)*(INDIRECT($R$1&"!$H:$H")>=M11),INDIRECT($R$1&"!$L:$L"))))} -> 40.3 | Q11: {=(_xlfn.SINGLE(_xlfn.XLOOKUP(1,(INDIRECT($R$1&"!$C:$C")=B11)*(INDIRECT($R$1&"!$G:$G")<N11)*(INDIRECT($R$1&"!$H:$H")>=N11),INDIRECT($R$1&"!$K:$K"))))*N11+(_xlfn.SINGLE(_xlfn.XLOOKUP(1,(INDIRECT($R$1&"!$C:$C")=B11)*(INDIRECT($R$1&"!$G:$G")<N11)*(INDIRECT($R$1&"!$H:$H")>=N11),INDIRECT($R$1&"!$L:$L"))))} -> 47.45
A12: 卢森堡 | B12: LU | C12: =(F12+I12)*(1+$F$1) -> 7.5728873 | D12: =(G12+J12)*(1+$F$1) -> 10.926056 | E12: =(H12+K12)*(1+$F$1) -> 14.279225 | F12: =O12/$P$1 -> 5.1056338 | G12: =P12/$P$1 -> 6.2676056 | H12: =Q12/$P$1 -> 7.4295775 | I12: =(VLOOKUP($B$1,'Product Procurement Sheet'!B:I,8,0)*$L$1)/$P$1 -> 1.971831 | J12: =(VLOOKUP($B$1,'Product Procurement Sheet'!B:I,8,0)*$M$1)/$P$1 -> 3.943662 | K12: =(VLOOKUP($B$1,'Product Procurement Sheet'!B:I,8,0)*$N$1)/$P$1 -> 5.915493 | L12: =VLOOKUP($B$1,'Product Procurement Sheet'!B:D,3,FALSE)*$L$1 -> 0.11 | M12: =VLOOKUP($B$1,'Product Procurement Sheet'!B:D,3,FALSE)*$M$1 -> 0.22 | N12: =VLOOKUP($B$1,'Product Procurement Sheet'!B:D,3,FALSE)*$N$1 -> 0.33 | O12: {=(_xlfn.SINGLE(_xlfn.XLOOKUP(1,(INDIRECT($R$1&"!$C:$C")=B12)*(INDIRECT($R$1&"!$G:$G")<L12)*(INDIRECT($R$1&"!$H:$H")>=L12),INDIRECT($R$1&"!$K:$K"))))*L12+(_xlfn.SINGLE(_xlfn.XLOOKUP(1,(INDIRECT($R$1&"!$C:$C")=B12)*(INDIRECT($R$1&"!$G:$G")<L12)*(INDIRECT($R$1&"!$H:$H")>=L12),INDIRECT($R$1&"!$L:$L"))))} -> 36.25 | P12: {=(_xlfn.SINGLE(_xlfn.XLOOKUP(1,(INDIRECT($R$1&"!$C:$C")=B12)*(INDIRECT($R$1&"!$G:$G")<M12)*(INDIRECT($R$1&"!$H:$H")>=M12),INDIRECT($R$1&"!$K:$K"))))*M12+(_xlfn.SINGLE(_xlfn.XLOOKUP(1,(INDIRECT($R$1&"!$C:$C")=B12)*(INDIRECT($R$1&"!$G:$G")<M12)*(INDIRECT($R$1&"!$H:$H")>=M12),INDIRECT($R$1&"!$L:$L"))))} -> 44.5 | Q12: {=(_xlfn.SINGLE(_xlfn.XLOOKUP(1,(INDIRECT($R$1&"!$C:$C")=B12)*(INDIRECT($R$1&"!$G:$G")<N12)*(INDIRECT($R$1&"!$H:$H")>=N12),INDIRECT($R$1&"!$K:$K"))))*N12+(_xlfn.SINGLE(_xlfn.XLOOKUP(1,(INDIRECT($R$1&"!$C:$C")=B12)*(INDIRECT($R$1&"!$G:$G")<N12)*(INDIRECT($R$1&"!$H:$H")>=N12),INDIRECT($R$1&"!$L:$L"))))} -> 52.75
A13: 爱尔兰 | B13: IE | C13: =(F13+I13)*(1+$F$1) -> 6.955 | D13: =(G13+J13)*(1+$F$1) -> 10.142394 | E13: =(H13+K13)*(1+$F$1) -> 13.329789 | F13: =O13/$P$1 -> 4.528169 | G13: =P13/$P$1 -> 5.5352113 | H13: =Q13/$P$1 -> 6.5422535 | I13: =(VLOOKUP($B$1,'Product Procurement Sheet'!B:I,8,0)*$L$1)/$P$1 -> 1.971831 | J13: =(VLOOKUP($B$1,'Product Procurement Sheet'!B:I,8,0)*$M$1)/$P$1 -> 3.943662 | K13: =(VLOOKUP($B$1,'Product Procurement Sheet'!B:I,8,0)*$N$1)/$P$1 -> 5.915493 | L13: =VLOOKUP($B$1,'Product Procurement Sheet'!B:D,3,FALSE)*$L$1 -> 0.11 | M13: =VLOOKUP($B$1,'Product Procurement Sheet'!B:D,3,FALSE)*$M$1 -> 0.22 | N13: =VLOOKUP($B$1,'Product Procurement Sheet'!B:D,3,FALSE)*$N$1 -> 0.33 | O13: {=(_xlfn.SINGLE(_xlfn.XLOOKUP(1,(INDIRECT($R$1&"!$C:$C")=B13)*(INDIRECT($R$1&"!$G:$G")<L13)*(INDIRECT($R$1&"!$H:$H")>=L13),INDIRECT($R$1&"!$K:$K"))))*L13+(_xlfn.SINGLE(_xlfn.XLOOKUP(1,(INDIRECT($R$1&"!$C:$C")=B13)*(INDIRECT($R$1&"!$G:$G")<L13)*(INDIRECT($R$1&"!$H:$H")>=L13),INDIRECT($R$1&"!$L:$L"))))} -> 32.15 | P13: {=(_xlfn.SINGLE(_xlfn.XLOOKUP(1,(INDIRECT($R$1&"!$C:$C")=B13)*(INDIRECT($R$1&"!$G:$G")<M13)*(INDIRECT($R$1&"!$H:$H")>=M13),INDIRECT($R$1&"!$K:$K"))))*M13+(_xlfn.SINGLE(_xlfn.XLOOKUP(1,(INDIRECT($R$1&"!$C:$C")=B13)*(INDIRECT($R$1&"!$G:$G")<M13)*(INDIRECT($R$1&"!$H:$H")>=M13),INDIRECT($R$1&"!$L:$L"))))} -> 39.3 | Q13: {=(_xlfn.SINGLE(_xlfn.XLOOKUP(1,(INDIRECT($R$1&"!$C:$C")=B13)*(INDIRECT($R$1&"!$G:$G")<N13)*(INDIRECT($R$1&"!$H:$H")>=N13),INDIRECT($R$1&"!$K:$K"))))*N13+(_xlfn.SINGLE(_xlfn.XLOOKUP(1,(INDIRECT($R$1&"!$C:$C")=B13)*(INDIRECT($R$1&"!$G:$G")<N13)*(INDIRECT($R$1&"!$H:$H")>=N13),INDIRECT($R$1&"!$L:$L"))))} -> 46.45
A14: 保加利亚 | B14: BG | C14: =(F14+I14)*(1+$F$1) -> 4.7245775 | D14: =(G14+J14)*(1+$F$1) -> 8.2435211 | E14: =(H14+K14)*(1+$F$1) -> 11.762465 | F14: =O14/$P$1 -> 2.443662 | G14: =P14/$P$1 -> 3.7605634 | H14: =Q14/$P$1 -> 5.0774648 | I14: =(VLOOKUP($B$1,'Product Procurement Sheet'!B:I,8,0)*$L$1)/$P$1 -> 1.971831 | J14: =(VLOOKUP($B$1,'Product Procurement Sheet'!B:I,8,0)*$M$1)/$P$1 -> 3.943662 | K14: =(VLOOKUP($B$1,'Product Procurement Sheet'!B:I,8,0)*$N$1)/$P$1 -> 5.915493 | L14: =VLOOKUP($B$1,'Product Procurement Sheet'!B:D,3,FALSE)*$L$1 -> 0.11 | M14: =VLOOKUP($B$1,'Product Procurement Sheet'!B:D,3,FALSE)*$M$1 -> 0.22 | N14: =VLOOKUP($B$1,'Product Procurement Sheet'!B:D,3,FALSE)*$N$1 -> 0.33 | O14: {=(_xlfn.SINGLE(_xlfn.XLOOKUP(1,(INDIRECT($R$1&"!$C:$C")=B14)*(INDIRECT($R$1&"!$G:$G")<L14)*(INDIRECT($R$1&"!$H:$H")>=L14),INDIRECT($R$1&"!$K:$K"))))*L14+(_xlfn.SINGLE(_xlfn.XLOOKUP(1,(INDIRECT($R$1&"!$C:$C")=B14)*(INDIRECT($R$1&"!$G:$G")<L14)*(INDIRECT($R$1&"!$H:$H")>=L14),INDIRECT($R$1&"!$L:$L"))))} -> 17.35 | P14: {=(_xlfn.SINGLE(_xlfn.XLOOKUP(1,(INDIRECT($R$1&"!$C:$C")=B14)*(INDIRECT($R$1&"!$G:$G")<M14)*(INDIRECT($R$1&"!$H:$H")>=M14),INDIRECT($R$1&"!$K:$K"))))*M14+(_xlfn.SINGLE(_xlfn.XLOOKUP(1,(INDIRECT($R$1&"!$C:$C")=B14)*(INDIRECT($R$1&"!$G:$G")<M14)*(INDIRECT($R$1&"!$H:$H")>=M14),INDIRECT($R$1&"!$L:$L"))))} -> 26.7 | Q14: {=(_xlfn.SINGLE(_xlfn.XLOOKUP(1,(INDIRECT($R$1&"!$C:$C")=B14)*(INDIRECT($R$1&"!$G:$G")<N14)*(INDIRECT($R$1&"!$H:$H")>=N14),INDIRECT($R$1&"!$K:$K"))))*N14+(_xlfn.SINGLE(_xlfn.XLOOKUP(1,(INDIRECT($R$1&"!$C:$C")=B14)*(INDIRECT($R$1&"!$G:$G")<N14)*(INDIRECT($R$1&"!$H:$H")>=N14),INDIRECT($R$1&"!$L:$L"))))} -> 36.05
A15: 克罗地亚 | B15: CRO | C15: =(F15+I15)*(1+$F$1) -> #N/A | D15: =(G15+J15)*(1+$F$1) -> #N/A | E15: =(H15+K15)*(1+$F$1) -> #N/A | F15: =O15/$P$1 -> #N/A | G15: =P15/$P$1 -> #N/A | H15: =Q15/$P$1 -> #N/A | I15: =(VLOOKUP($B$1,'Product Procurement Sheet'!B:I,8,0)*$L$1)/$P$1 -> 1.971831 | J15: =(VLOOKUP($B$1,'Product Procurement Sheet'!B:I,8,0)*$M$1)/$P$1 -> 3.943662 | K15: =(VLOOKUP($B$1,'Product Procurement Sheet'!B:I,8,0)*$N$1)/$P$1 -> 5.915493 | L15: =VLOOKUP($B$1,'Product Procurement Sheet'!B:D,3,FALSE)*$L$1 -> 0.11 | M15: =VLOOKUP($B$1,'Product Procurement Sheet'!B:D,3,FALSE)*$M$1 -> 0.22 | N15: =VLOOKUP($B$1,'Product Procurement Sheet'!B:D,3,FALSE)*$N$1 -> 0.33 | O15: {=(_xlfn.SINGLE(_xlfn.XLOOKUP(1,(INDIRECT($R$1&"!$C:$C")=B15)*(INDIRECT($R$1&"!$G:$G")<L15)*(INDIRECT($R$1&"!$H:$H")>=L15),INDIRECT($R$1&"!$K:$K"))))*L15+(_xlfn.SINGLE(_xlfn.XLOOKUP(1,(INDIRECT($R$1&"!$C:$C")=B15)*(INDIRECT($R$1&"!$G:$G")<L15)*(INDIRECT($R$1&"!$H:$H")>=L15),INDIRECT($R$1&"!$L:$L"))))} -> #N/A | P15: {=(_xlfn.SINGLE(_xlfn.XLOOKUP(1,(INDIRECT($R$1&"!$C:$C")=B15)*(INDIRECT($R$1&"!$G:$G")<M15)*(INDIRECT($R$1&"!$H:$H")>=M15),INDIRECT($R$1&"!$K:$K"))))*M15+(_xlfn.SINGLE(_xlfn.XLOOKUP(1,(INDIRECT($R$1&"!$C:$C")=B15)*(INDIRECT($R$1&"!$G:$G")<M15)*(INDIRECT($R$1&"!$H:$H")>=M15),INDIRECT($R$1&"!$L:$L"))))} -> #N/A | Q15: {=(_xlfn.SINGLE(_xlfn.XLOOKUP(1,(INDIRECT($R$1&"!$C:$C")=B15)*(INDIRECT($R$1&"!$G:$G")<N15)*(INDIRECT($R$1&"!$H:$H")>=N15),INDIRECT($R$1&"!$K:$K"))))*N15+(_xlfn.SINGLE(_xlfn.XLOOKUP(1,(INDIRECT($R$1&"!$C:$C")=B15)*(INDIRECT($R$1&"!$G:$G")<N15)*(INDIRECT($R$1&"!$H:$H")>=N15),INDIRECT($R$1&"!$L:$L"))))} -> #N/A
... A221: 俄罗斯 | B221: RU | C221: =(F221+I221)*(1+$F$1) -> 4.3478169 | D221: =(G221+J221)*(1+$F$1) -> 7.0378873 | E221: =(H221+K221)*(1+$F$1) -> 9.7279577 | F221: =O221/$P$1 -> 2.0915493 | G221: =P221/$P$1 -> 2.6338028 | H221: =Q221/$P$1 -> 3.1760563 | I221: =(VLOOKUP($B$1,'Product Procurement Sheet'!B:I,8,0)*$L$1)/$P$1 -> 1.971831 | J221: =(VLOOKUP($B$1,'Product Procurement Sheet'!B:I,8,0)*$M$1)/$P$1 -> 3.943662 | K221: =(VLOOKUP($B$1,'Product Procurement Sheet'!B:I,8,0)*$N$1)/$P$1 -> 5.915493 | L221: =VLOOKUP($B$1,'Product Procurement Sheet'!B:D,3,FALSE)*$L$1 -> 0.11 | M221: =VLOOKUP($B$1,'Product Procurement Sheet'!B:D,3,FALSE)*$M$1 -> 0.22 | N221: =VLOOKUP($B$1,'Product Procurement Sheet'!B:D,3,FALSE)*$N$1 -> 0.33 | O221: {=(_xlfn.SINGLE(_xlfn.XLOOKUP(1,(INDIRECT($R$1&"!$C:$C")=B221)*(INDIRECT($R$1&"!$G:$G")<L221)*(INDIRECT($R$1&"!$H:$H")>=L221),INDIRECT($R$1&"!$K:$K"))))*L221+(_xlfn.SINGLE(_xlfn.XLOOKUP(1,(INDIRECT($R$1&"!$C:$C")=B221)*(INDIRECT($R$1&"!$G:$G")<L221)*(INDIRECT($R$1&"!$H:$H")>=L221),INDIRECT($R$1&"!$L:$L"))))} -> 14.85 | P221: {=(_xlfn.SINGLE(_xlfn.XLOOKUP(1,(INDIRECT($R$1&"!$C:$C")=B221)*(INDIRECT($R$1&"!$G:$G")<M221)*(INDIRECT($R$1&"!$H:$H")>=M221),INDIRECT($R$1&"!$K:$K"))))*M221+(_xlfn.SINGLE(_xlfn.XLOOKUP(1,(INDIRECT($R$1&"!$C:$C")=B221)*(INDIRECT($R$1&"!$G:$G")<M221)*(INDIRECT($R$1&"!$H:$H")>=M221),INDIRECT($R$1&"!$L:$L"))))} -> 18.7 | Q221: {=(_xlfn.SINGLE(_xlfn.XLOOKUP(1,(INDIRECT($R$1&"!$C:$C")=B221)*(INDIRECT($R$1&"!$G:$G")<N221)*(INDIRECT($R$1&"!$H:$H")>=N221),INDIRECT($R$1&"!$K:$K"))))*N221+(_xlfn.SINGLE(_xlfn.XLOOKUP(1,(INDIRECT($R$1&"!$C:$C")=B221)*(INDIRECT($R$1&"!$G:$G")<N221)*(INDIRECT($R$1&"!$H:$H")>=N221),INDIRECT($R$1&"!$L:$L"))))} -> 22.55

Sheet Product Procurement Sheet
A1: 产品名字（Product name） | B1: 产品编码Product type | C1: 产品图片Product image | D1: 计算重量Calculate weight | E1: unit weight单个重量KG | F1: 材积重Volume weight | G1: 包装尺寸Size | H1: 产品尺寸 | I1: unit price商品价格 | J1: shipping fee to warehouse报价运费 | K1: Real shipping cost真实运费 | L1: Client name客户名称 | M1: 报价产品参考链接Quote product reference link | N1: 颜色color | O1: 英文标题English title | P1: 1688link链接 | Q1: 报价员 | R1: 是否在售
A2: Electric Guasha Scraping Massage Tool | B2: EQU0530001A | C2: =_xlfn.DISPIMG("ID_3364B878065D4633BFDA16464000B2C5",1) -> =DISPIMG("ID_3364B878065D4633BFDA16464000B2C5",1) | D2: =MAX(E2,F2) -> 0.49 | E2: 0.49 | F2: =15*15*12/8000 -> 0.3375 | G2: 72.5*19*44cm | H2: 13*12cm | I2: =K2+J2 -> 55 | J2: 55 | K2: 0 | M2: 下单后2天左右发货 | P2: https://detail.1688.com/offer/667310265863.html?spm=a26352.b28411319.offerlist.16.1e291e62ZadNuJ | R2: =_xlfn.DISPIMG("ID_E506C151F08B445E982424171EA278F5",1) -> =DISPIMG("ID_E506C151F08B445E982424171EA278F5",1) | S2: =_xlfn.DISPIMG("ID_9060D06700234D73A40A37F2370E2234",1) -> =DISPIMG("ID_9060D06700234D73A40A37F2370E2234",1) | T2: =_xlfn.DISPIMG("ID_0489DDD773654DA19EF5D2F7E6CFF583",1) -> =DISPIMG("ID_0489DDD773654DA19EF5D2F7E6CFF583",1)
B3: EQU0530002A | D3: =MAX(E3,F3) -> 0.49 | E3: 0.49 | F3: =15*15*12/8000 -> 0.3375 | G3: 72.5*19*44cm | H3: 13*12cm | I3: =K3+J3 -> 52 | J3: 52 | K3: 0
B4: EQU0530001B | C4: 捆绑价格 | D4: =MAX(E4,F4) -> 0.59 | E4: =0.1+E2 -> 0.59 | F4: =17*17*11/8000 -> 0.397375 | G4: 17*17*11cm | I4: 57 | J4: 60
B5: EQU0530002B | C5: 1+A | D5: =MAX(E5,F5) -> 0.59 | E5: =0.1+E3 -> 0.59 | F5: =17*17*11/8000 -> 0.397375 | I5: 60 | J5: 57
B6: EQU0530001C | C6: 1+2A | D6: =MAX(E6,F6) -> 1.404 | E6: =0.65 -> 0.65 | F6: =26*18*15/5000 -> 1.404 | G6: 26*18*15 | I6: 65
B7: EQU0530002C | D7: =MAX(E7,F7) -> 1.404 | E7: =0.65 -> 0.65 | F7: =26*18*15/5000 -> 1.404 | I7: 72
B8: EQU0530001D | D8: =MAX(E8,F8) -> 0 | I8: 73 | J8: 68
B9: EQU0530002D | D9: =MAX(E9,F9) -> 0 | I9: 80 | J9: 65
D10: =MAX(E10,F10) -> 0
D11: =MAX(E11,F11) -> 0
D12: =MAX(E12,F12) -> 0
D13: =MAX(E13,F13) -> 0
B14: E001 | C14: 1+1纸箱 | D14: =MAX(E14,F14) -> 1.4976 | E14: 0.58 | F14: =16*26*18/5000 -> 1.4976 | G14: 16*26*18 | I14: 60
B15: ZK001 | C15: 折扣 | D15: =MAX(E15,F15) -> 1.4976 | E15: 0.58 | F15: =16*26*18/5000 -> 1.4976 | G15: 16*26*18 | I15: 57
B16: E002 | C16: 1+2纸箱 | D16: =MAX(E16,F16) -> 1.4976 | E16: 0.65 | F16: =16*26*18/5000 -> 1.4976 | I16: 65
B17: ZK002 | C17: 折扣 | D17: =MAX(E17,F17) -> 1.4976 | E17: 0.65 | F17: =16*26*18/5000 -> 1.4976 | I17: 62
B18: E003 | C18: 1+1气泡袋 | D18: =MAX(E18,F18) -> 0.8228 | E18: 0.55 | F18: =22*11*17/5000 -> 0.8228 | I18: 60
A19: ZK003 | B19: ZK003 | C19: 折扣 | D19: =MAX(E19,F19) -> 0.8228 | E19: 0.55 | F19: =22*11*17/5000 -> 0.8228 | I19: 57
A20: ZK004 | B20: E004 | C20: 1+2气泡袋 | D20: =MAX(E20,F20) -> 0.8228 | E20: 0.6 | F20: =22*11*17/5000 -> 0.8228 | I20: 65
A21: ZK005 | B21: ZK004 | C21: 折扣 | D21: =MAX(E21,F21) -> 0.8228 | E21: 0.6 | F21: =22*11*17/5000 -> 0.8228 | I21: 62
A22: ZK006 | B22: E005 | C22: 1+1塑料袋 | D22: =MAX(E22,F22) -> 0.9936 | E22: 0.57 | F22: =23*12*18/5000 -> 0.9936 | I22: 60
B23: ZK005 | C23: 折扣 | D23: =MAX(E23,F23) -> 0.9936 | E23: 0.57 | F23: =23*12*18/5000 -> 0.9936 | I23: 57
B24: E006 | C24: 1+2塑料袋 | D24: =MAX(E24,F24) -> 0.9936 | E24: 0.64 | F24: =23*12*18/5000 -> 0.9936 | I24: 65
B25: ZK006 | C25: 折扣 | D25: =MAX(E25,F25) -> 0.9936 | E25: 0.64 | F25: =23*12*18/5000 -> 0.9936 | I25: 62
A26: Oil of Oregano | B26: 相似款 | C26: =_xlfn.DISPIMG("ID_4CEC0291335C40FEA5F4AE73D1DA7B81",1) -> =DISPIMG("ID_4CEC0291335C40FEA5F4AE73D1DA7B81",1) | D26: =MAX(E26,F26) -> 0.11 | E26: 0.11 | G26: 高19.5宽13.5cm | I26: =K26+J26 -> 46 | J26: 38 | K26: 8 | M26: https://resilia.shop/collections/best-sellers/products/resilia%E2%84%A2-oil-of-oregano-softgels | P26: https://detail.1688.com/offer/910982119982.html?spm=a26352.b28411319.offerlist.1.6b2d1e62zrDVua | R26: =_xlfn.DISPIMG("ID_C09B1D0D3170446FA4B66A36A8211A98",1) -> =DISPIMG("ID_C09B1D0D3170446FA4B66A36A8211A98",1) | T26: 牛至油180粒，牛至油300粒，有两种
A27: SafeMag™ | Auto-Telefonhalterung [Letzter Tag Rabatt] | B27: GQU0623007相似款 | C27: =_xlfn.DISPIMG("ID_D346022E158E415E8753332547B85756",1) -> =DISPIMG("ID_D346022E158E415E8753332547B85756",1) | D27: =MAX(E27,F27) -> 0.3 | E27: 0.3 | F27: 0.032 | G27: 16×8×2 | H27: =_xlfn.DISPIMG("ID_43E8A72E216946CD9CCF379A4D4FD3B1",1) -> =DISPIMG("ID_43E8A72E216946CD9CCF379A4D4FD3B1",1) | I27: =K27+J27 -> 14.8 | J27: 11.8 | K27: 3 | M27: https://cendura.de/products/safemag-auto-telefonhalterung-letzter-tag-rabatt?_pos=1&_sid=8f51d7273&_ss=r%3Fvariant%3D55375716974970&variant=55375716974970 | P27: https://detail.1688.com/offer/879429116969.html?spm=a26352.b28411319.offerlist.214.6ac71e627r4aTM | R27: =_xlfn.DISPIMG("ID_BB0EFDFF97E64B3FB5389E91B896FF87",1) -> =DISPIMG("ID_BB0EFDFF97E64B3FB5389E91B896FF87",1)
A28: a) Handwinding Steel Watch (no electronics!) b) Book | B28: CQU0623001 | D28: =MAX(E28,F28) -> 0.6 | E28: 0.6 | F28: =22*15*8/5000 -> 0.528 | G28: 22*15*8 | I28: =K28+J28 -> 0 | J28: 0
A29: Handwinding Steel Watch (no electronics!) | B29: CQU0623110 | D29: =MAX(E29,F29) -> 0.4 | E29: 0.4 | F29: =19*12*6/5000 -> 0.2736 | G29: 19*12*6 | I29: =K29+J29 -> 0 | J29: 0
A30: Pedicure set + foot cream + 3*socks | B30: G0101-ME | C30: =_xlfn.DISPIMG("ID_1C9B3D3D817644D4B78D65D02A3FCDC7",1) -> =DISPIMG("ID_1C9B3D3D817644D4B78D65D02A3FCDC7",1) | D30: =MAX(E30,F30) -> 1.40625 | E30: 1 | F30: =30*25*15/8000 -> 1.40625 | G30: 30*25*15 | I30: 89
C31: =_xlfn.DISPIMG("ID_1AAD8B113C5F40939CCB0D9A51D1A44E",1) -> =DISPIMG("ID_1AAD8B113C5F40939CCB0D9A51D1A44E",1)
C32: =_xlfn.DISPIMG("ID_CA728C4165EF4B59886C0000AA4B8871",1) -> =DISPIMG("ID_CA728C4165EF4B59886C0000AA4B8871",1)
B33: E011 | C33: 1+1纸箱 | D33: =MAX(E33,F33) -> 1.4976 | E33: 0.58 | F33: =16*26*18/5000 -> 1.4976 | G33: 16*26*18 | I33: 0
B34: E013 | C34: 1+1塑料袋 | D34: =MAX(E34,F34) -> 0.8228 | E34: 0.55 | F34: =22*11*17/5000 -> 0.8228 | I34: 0
B35: E015 | C35: 1+1气泡袋 | D35: =MAX(E35,F35) -> 0.9936 | E35: 0.57 | F35: =23*12*18/5000 -> 0.9936 | I35: 0
A36: SkinGuard（1+1） | B36: GQU0630007 | C36: =_xlfn.DISPIMG("ID_76C88E4864A1475AAEDF103B5BDFD722",1) -> =DISPIMG("ID_76C88E4864A1475AAEDF103B5BDFD722",1) | D36: =MAX(E36,F36) -> 0.2 | E36: 0.2 | F36: =4*4*13/8000 -> 0.026 | G36: 4*4*13 | I36: =K36+J36 -> 26 | J36: 18 | K36: 8 | M36: https://lettucepets.com/products/pet-skin-treatment-spray-for-fungal-bacterial-infections?fbclid=IwY2xjawLPJKZleHRuA2FlbQIxMABicmlkETFJSU9yaTNBWEpjMkJpOXYxAR4shII-NJrs6eU9LWfVqSfPIsAB3IHewhA5WNMVKYeYQhsg0Q3816RR9wV9bw_aem_Nu3h6lEgB8GK2w8WlMLxrQ&variant=51233243562268 | P36: https://detail.1688.com/offer/940558935118.html?spm=a26352.b28411319.offerlist.1.6a001e620BDgLt | R36: =_xlfn.DISPIMG("ID_E00E39BEDCA14554BDB0F00C36D2FA85",1) -> =DISPIMG("ID_E00E39BEDCA14554BDB0F00C36D2FA85",1) | S36: =_xlfn.DISPIMG("ID_54B898D5F6A64BE89EAF26AC2C7026BF",1) -> =DISPIMG("ID_54B898D5F6A64BE89EAF26AC2C7026BF",1) | T36: =_xlfn.DISPIMG("ID_2598C4EDDE854AAEAAB7E65068067D87",1) -> =DISPIMG("ID_2598C4EDDE854AAEAAB7E65068067D87",1)
A37: Neck Pain Patches | B37: GQU0630008 | C37: =_xlfn.DISPIMG("ID_21427AE04695476D86E80F4D9BA814FA",1) -> =DISPIMG("ID_21427AE04695476D86E80F4D9BA814FA",1) | D37: =MAX(E37,F37) -> 0.03 | E37: 0.03 | I37: =K37+J37 -> 3.7 | J37: 0.5 | K37: 3.2 | M37: https://www.amazon.com/iShanCare-Neck-Pain-Relief-Patch/dp/B0BKL4NRMQ/ref=sims_dp_d_dex_ai_rank_model_feedback_d_v1_d_sccl_1_2/136-0509895-9428936?pd_rd_w=A2qmS&content-id=amzn1.sym.5daa61ea-dedc-4cc4-b84a-9865d4f36e97&pf_rd_p=5daa61ea-dedc-4cc4-b84a-9865d4f36e97&pf_rd_r=CB9PPYGYQ1H0HQRB9ZJR&pd_rd_wg=m4Buk&pd_rd_r=ceb79ee7-5477-49d7-85aa-c32ec9c0073e&pd_rd_i=B0BKL4NRMQ&th=1 | P37: https://detail.1688.com/offer/937927916764.html?spm=a26352.b28411319.offerlist.1.3da51e62IS8wCp | R37: =_xlfn.DISPIMG("ID_A9FB0D7102DA4F0A8B4AB78C8A981922",1) -> =DISPIMG("ID_A9FB0D7102DA4F0A8B4AB78C8A981922",1) | S37: =_xlfn.DISPIMG("ID_04BAE11DCE934B8FA61B08075A755D2A",1) -> =DISPIMG("ID_04BAE11DCE934B8FA61B08075A755D2A",1)
A38: Combined Quote （1 massager+ 1pack patches） "Blue Neck Massager Neck Pain Patches" | B38: GQU0630009 | C38: =_xlfn.DISPIMG("ID_75473907AF9F4913A71673C19029E4A6",1) -> =DISPIMG("ID_75473907AF9F4913A71673C19029E4A6",1) | D38: =MAX(E38,F38) -> 1.125 | E38: 0.8 | F38: =24*25*15/8000 -> 1.125 | G38: 24*25*15cm | I38: =K38+J38 -> 133.7 | J38: 130.5 | K38: 3.2 | M38: https://www.amazon.com/iShanCare-Neck-Pain-Relief-Patch/dp/B0BKL4NRMQ/ref=sims_dp_d_dex_ai_rank_model_feedback_d_v1_d_sccl_1_2/136-0509895-9428936?pd_rd_w=A2qmS&content-id=amzn1.sym.5daa61ea-dedc-4cc4-b84a-9865d4f36e97&pf_rd_p=5daa61ea-dedc-4cc4-b84a-9865d4f36e97&pf_rd_r=CB9PPYGYQ1H0HQRB9ZJR&pd_rd_wg=m4Buk&pd_rd_r=ceb79ee7-5477-49d7-85aa-c32ec9c0073e&pd_rd_i=B0BKL4NRMQ&th=1 | P38: https://detail.1688.com/offer/937927916764.html?spm=a26352.b28411319.offerlist.1.3da51e62IS8wCp | R38: =_xlfn.DISPIMG("ID_A9FB0D7102DA4F0A8B4AB78C8A981922",1) -> =DISPIMG("ID_A9FB0D7102DA4F0A8B4AB78C8A981922",1) | S38: =_xlfn.DISPIMG("ID_04BAE11DCE934B8FA61B08075A755D2A",1) -> =DISPIMG("ID_04BAE11DCE934B8FA61B08075A755D2A",1)
C39: =_xlfn.DISPIMG("ID_CE8BDEC5B531425692465B8395A482C6",1) -> =DISPIMG("ID_CE8BDEC5B531425692465B8395A482C6",1) | I39: =K39+J39 -> 0
A40: Gluco Gone Blood Sugar Regulating Drops | B40: LQU0702101 | C40: =_xlfn.DISPIMG("ID_95B666FFAE3449AFA339E29AA544F9C8",1) -> =DISPIMG("ID_95B666FFAE3449AFA339E29AA544F9C8",1) | D40: =MAX(E40,F40) -> 0.2 | E40: 0.2 | F40: =15*5*5/5000 -> 0.075 | G40: 15*5*5 | I40: =K40+J40 -> 19 | J40: 15 | K40: 4 | M40: https://navanisupps.com/products/droplets | P40: https://detail.1688.com/offer/901924596865.html?spm=a26352.b28411319.offerlist.57.4ccb1e625tdpoO
...

Sheet 华翰特敏
F1: 全球专线-特敏 | N1: 生效日期：2025.07.21 9:00 | O1: 返回目录
B2: 国家 | F2: 重量段KG | K2: 运费 RMB/KG | L2: 挂号费 RMB/票 | M2: 尺寸限制cm | N2: 参考时效（工作日）
B3: 加拿大 | C3: CA | F3: 0.05≤W≤0.3 | G3: 0.05 | H3: 0.3 | K3: 113 | L3: 29 | M3: 最长边≤60cm；长+宽+高≤90cm 最小尺寸≥15x10x1cm | N3: 9-15
B4: 加拿大 | C4: CA | F4: 0.3<W≤0.75 | G4: 0.3 | H4: 0.75 | K4: 113 | L4: 29
B5: 加拿大 | C5: CA | F5: 0.75<W≤1 | G5: 0.75 | H5: 1 | K5: 113 | L5: 29
B6: 加拿大 | C6: CA | F6: 1<W≤1.5 | G6: 1 | H6: 1.5 | K6: 113 | L6: 29
B7: 加拿大 | C7: CA | F7: 1.5<W≤2 | G7: 1.5 | H7: 2 | K7: 109 | L7: 29
B8: 加拿大 | C8: CA | F8: 2<W≤15 | G8: 2 | H8: 15 | K8: 109 | L8: 29
B9: 英国 | C9: UK/GB | F9: 0.01≤W≤1 | G9: 0.01 | H9: 1 | K9: 112 | L9: 17 | M9: 最大尺寸<60x40x40cm 最小尺寸≥15x10x1cm | N9: 6-10
B10: 英国 | C10: UK/GB | F10: 1<W≤2 | G10: 1 | H10: 2 | K10: 103 | L10: 17 | O10: 英国-Royal Mail偏远邮编
B11: 英国 | C11: UK/GB | F11: 2<W≤10 | G11: 2 | H11: 10 | K11: 103 | L11: 17
B12: 德国 | C12: DE | F12: 0.01≤W≤1 | G12: 0.01 | H12: 1 | K12: 102 | L12: 24 | M12: 0<W≤1：最大尺寸≤ 35x25x10cm 1<W≤10：最大尺寸≤ 60x50x40cm 最小尺寸≥15x10x1cm Packstation：尺寸限制<60x30x30cm | N12: 8-12
B13: 德国 | C13: DE | F13: 1<W≤2 | G13: 1 | H13: 2 | K13: 102 | L13: 24
B14: 德国 | C14: DE | F14: 2<W≤10 | G14: 2 | H14: 10 | K14: 102 | L14: 24
B15: 法国 | C15: FR | F15: 0.01≤W≤1 | G15: 0.01 | H15: 1 | K15: 110 | L15: 31 | M15: 最大尺寸≤60x50x40cm 最小尺寸≥15x10x1cm | N15: 8-12
B16: 法国 | C16: FR | F16: 1<W≤2 | G16: 1 | H16: 2 | K16: 110 | L16: 31
B17: 法国 | C17: FR | F17: 2<W≤10 | G17: 2 | H17: 10 | K17: 110 | L17: 31
B18: 意大利 | C18: IT | F18: 0.01≤W≤1 | G18: 0.01 | H18: 1 | K18: 123 | L18: 34 | M18: 最大尺寸≤60x50x40cm 最小尺寸≥15x10x1cm | N18: 8-12
B19: 意大利 | C19: IT | F19: 1<W≤2 | G19: 1 | H19: 2 | K19: 123 | L19: 34
B20: 意大利 | C20: IT | F20: 2<W≤10 | G20: 2 | H20: 10 | K20: 123 | L20: 34
B21: 西班牙 | C21: ES | F21: 0.01≤W≤1 | G21: 0.01 | H21: 1 | K21: 121 | L21: 27 | M21: 最大尺寸≤60x50x40cm 最小尺寸≥15x10x1cm | N21: 8-12
B22: 西班牙 | C22: ES | F22: 1<W≤2 | G22: 1 | H22: 2 | K22: 121 | L22: 27
B23: 西班牙 | C23: ES | F23: 2<W≤10 | G23: 2 | H23: 10 | K23: 121 | L23: 27
B24: 葡萄牙 | C24: PT | F24: 0.01≤W≤1 | G24: 0.01 | H24: 1 | K24: 126 | L24: 27 | M24: 最大尺寸≤60x50x40cm 最小尺寸≥15x10x1cm | N24: 8-12
B25: 葡萄牙 | C25: PT | F25: 1<W≤2 | G25: 1 | H25: 2 | K25: 126 | L25: 27
B26: 葡萄牙 | C26: PT | F26: 2<W≤10 | G26: 2 | H26: 10 | K26: 126 | L26: 27
B27: 荷兰 | C27: NL | F27: 0.01≤W≤1 | G27: 0.01 | H27: 1 | K27: 123 | L27: 44 | M27: 最大尺寸≤60x50x40cm 最小尺寸≥15x10x1cm | N27: 8-12
B28: 荷兰 | C28: NL | F28: 1<W≤2 | G28: 1 | H28: 2 | K28: 123 | L28: 44
B29: 荷兰 | C29: NL | F29: 2<W≤10 | G29: 2 | H29: 10 | K29: 123 | L29: 44
B30: 比利时 | C30: BE | F30: 0.01≤W≤1 | G30: 0.01 | H30: 1 | K30: 109 | L30: 28 | M30: 最大尺寸≤60x50x40cm 最小尺寸≥15x10x1cm | N30: 8-12
B31: 比利时 | C31: BE | F31: 1<W≤2 | G31: 1 | H31: 2 | K31: 109 | L31: 28
B32: 比利时 | C32: BE | F32: 2<W≤10 | G32: 2 | H32: 10 | K32: 109 | L32: 28
B33: 卢森堡 | C33: LU | F33: 0.01≤W≤1 | G33: 0.01 | H33: 1 | K33: 103 | L33: 30 | M33: 最大尺寸≤60x50x40cm 最小尺寸≥15x10x1cm | N33: 8-12
B34: 卢森堡 | C34: LU | F34: 1<W≤2 | G34: 1 | H34: 2 | K34: 103 | L34: 30
B35: 卢森堡 | C35: LU | F35: 2<W≤10 | G35: 2 | H35: 10 | K35: 103 | L35: 30
B36: 瑞典 | C36: SE/SW | F36: 0.01≤W≤1 | G36: 0.01 | H36: 1 | K36: 117 | L36: 48 | M36: 最大尺寸≤60x50x40cm 最小尺寸≥15x10x1cm | N36: 8-12
B37: 瑞典 | C37: SE/SW | F37: 1<W≤2 | G37: 1 | H37: 2 | K37: 117 | L37: 48
B38: 瑞典 | C38: SE/SW | F38: 2<W≤10 | G38: 2 | H38: 10 | K38: 117 | L38: 48
B39: 奥地利 | C39: AT | F39: 0.01≤W≤1 | G39: 0.01 | H39: 1 | K39: 104 | L39: 37 | M39: 最大尺寸≤60x50x40cm 最小尺寸≥15x10x1cm | N39: 8-12
B40: 奥地利 | C40: AT | F40: 1<W≤2 | G40: 1 | H40: 2 | K40: 104 | L40: 26
...

Sheet 燕文普货
G1: 返回主目录
B2: 2025-07-16 00:00:00
B3: 481
B4: 国家 | C4: CountryCode | D4: 公斤运费(元/KG) | E4: 处理费(元/件) | F4: 重量段(KG) | M4: 最小计费重量(KG)
B5: 美国 | C5: US | D5: 120 | E5: 20 | F5: 0.001 - 0.1 | G5: 0.001 | H5: 0.1 | K5: 120 | L5: 20 | M5: 0.05
B6: 美国 | C6: US | D6: 114 | E6: 18 | F6: 0.101 - 0.2 | G6: 0.101 | H6: 0.2 | K6: 114 | L6: 18 | M6: 0.05
B7: 美国 | C7: US | D7: 110 | E7: 16 | F7: 0.201 - 0.45 | G7: 0.201 | H7: 0.45 | K7: 110 | L7: 16 | M7: 0.05
B8: 美国 | C8: US | D8: 103 | E8: 16 | F8: 0.451 - 0.7 | G8: 0.451 | H8: 0.7 | K8: 103 | L8: 16 | M8: 0.05
B9: 美国 | C9: US | D9: 103 | E9: 9 | F9: 0.701 - 1.5 | G9: 0.701 | H9: 1.5 | K9: 103 | L9: 9 | M9: 0.05
B10: 美国 | C10: US | D10: 103 | E10: 9 | F10: 1.501 - 2 | G10: 1.501 | H10: 2 | K10: 103 | L10: 9 | M10: 0.05
B11: 美国 | C11: US | D11: 96 | E11: 9 | F11: 2.001 - 30 | G11: 2.001 | H11: 30 | K11: 96 | L11: 9 | M11: 0.05
B12: 加拿大 | C12: CA | D12: 78 | E12: 21 | F12: 0.001 - 0.15 | G12: 0.001 | H12: 0.15 | K12: 78 | L12: 21 | M12: 0.05
B13: 加拿大 | C13: CA | D13: 79 | E13: 22 | F13: 0.151 - 0.45 | G13: 0.151 | H13: 0.45 | K13: 79 | L13: 22 | M13: 0.05
B14: 加拿大 | C14: CA | D14: 82 | E14: 23 | F14: 0.451 - 0.75 | G14: 0.451 | H14: 0.75 | K14: 82 | L14: 23 | M14: 0.05
B15: 加拿大 | C15: CA | D15: 83 | E15: 23 | F15: 0.751 - 1 | G15: 0.751 | H15: 1 | K15: 83 | L15: 23 | M15: 0.05
B16: 加拿大 | C16: CA | D16: 83 | E16: 23 | F16: 1.001 - 30 | G16: 1.001 | H16: 30 | K16: 83 | L16: 23 | M16: 0.05
... B27: 波多黎各 | C27: PR | D27: 108 | E27: 55 | F27: 2.001 - 30 | G27: 2.001 | H27: 30 | K27: 108 | L27: 55 | M27: 0.05
B28: 美国偏远地区 | C28: #N/A | D28: 103 | E28: 30 | F28: 0.001 - 0.1 | G28: 0.001 | H28: 0.1 | K28: 103 | L28: 30 | M28: 0.05
B29: 美国偏远地区 | C29: #N/A | D29: 103 | E29: 30 | F29: 0.101 - 0.2 | G29: 0.101 | H29: 0.2 | K29: 103 | L29: 30 | M29: 0.05
B30: 美国偏远地区 | C30: #N/A | D30: 103 | E30: 35 | F30: 0.201 - 0.34 | G30: 0.201 | H30: 0.34 | K30: 103 | L30: 35 | M30: 0.05
B31: 美国偏远地区 | C31: #N/A | D31: 103 | E31: 40 | F31: 0.341 - 0.45 | G31: 0.341 | H31: 0.45 | K31: 103 | L31: 40 | M31: 0.05
B32: 美国偏远地区 | C32: #N/A | D32: 108 | E32: 55 | F32: 0.451 - 0.7 | G32: 0.451 | H32: 0.7 | K32: 108 | L32: 55 | M32: 0.05
B33: 美国偏远地区 | C33: #N/A | D33: 108 | E33: 55 | F33: 0.701 - 1.5 | G33: 0.701 | H33: 1.5 | K33: 108 | L33: 55 | M33: 0.05
B34: 美国偏远地区 | C34: #N/A | D34: 108 | E34: 55 | F34: 1.501 - 2 | G34: 1.501 | H34: 2 | K34: 108 | L34: 55 | M34: 0.05
B35: 美国偏远地区 | C35: #N/A | D35: 108 | E35: 55 | F35: 2.001 - 30 | G35: 2.001 | H35: 30 | K35: 108 | L35: 55 | M35: 0.05
B36: 英国 | C36: UK/GB | D36: 68 | E36: 16 | F36: 0.001 - 1 | G36: 0.001 | H36: 1 | K36: 68 | L36: 16 | M36: 0.001
B37: 英国 | C37: UK/GB | D37: 70 | E37: 16 | F37: 1.001 - 20 | G37: 1.001 | H37: 20 | K37: 70 | L37: 16 | M37: 0.001
B38: 法国 | C38: FR | D38: 84 | E38: 18 | F38: 0.001 - 0.2 | G38: 0.001 | H38: 0.2 | K38: 84 | L38: 18 | M38: 0.001
B39: 法国 | C39: FR | D39: 82 | E39: 19 | F39: 0.201 - 0.5 | G39: 0.201 | H39: 0.5 | K39: 82 | L39: 19 | M39: 0.001
B40: 法国 | C40: FR | D40: 78 | E40: 23 | F40: 0.501 - 30 | G40: 0.501 | H40: 30 | K40: 78 | L40: 23 | M40: 0.001
B41: 德国 | C41: DE | D41: 70 | E41: 19 | F41: 0.001 - 0.3 | G41: 0.001 | H41: 0.3 | K41: 70 | L41: 19 | M41: 0.001
B42: 德国 | C42: DE | D42: 65 | E42: 22 | F42: 0.301 - 30 | G42: 0.301 | H42: 30 | K42: 65 | L42: 22 | M42: 0.001
B43: 意大利 | C43: IT | D43: 68 | E43: 25 | F43: 0.001 - 30 | G43: 0.001 | H43: 30 | K43: 68 | L43: 25 | M43: 0.001
B44: 西班牙 | C44: ES | D44: 74 | E44: 18 | F44: 0.001 - 30 | G44: 0.001 | H44: 30 | K44: 74 | L44: 18 | M44: 0.001
B45: 荷兰 | C45: NL | D45: 93 | E45: 21 | F45: 0.001 - 0.1 | G45: 0.001 | H45: 0.1 | K45: 93 | L45: 21 | M45: 0.001
B46: 荷兰 | C46: NL | D46: 83 | E46: 23 | F46: 0.101 - 0.2 | G46: 0.101 | H46: 0.2 | K46: 83 | L46: 23 | M46: 0.001
B47: 荷兰 | C47: NL | D47: 81 | E47: 23 | F47: 0.201 - 2 | G47: 0.201 | H47: 2 | K47: 81 | L47: 23 | M47: 0.001
... B162: 南非 | C162: ZA | D162: 171 | E162: 26 | F162: 0.001 - 8 | G162: 0.001 | H162: 8 | K162: 171 | L162: 26 | M162: 0.05
B163: 国家 | C163: CountryCode | D163: 重量段(KG) | E163: 首重 | F163: 首重价格 | H163: =RIGHT(F163,5) -> 首重价格 | M163: 续重
B164: 日本 | C164: JP | D164: 0.001 - 2 | E164: 0.5 | F164: 31 | G164: 0.001 | H164: 2 | K164: 31 | L164: 5 | M164: 0.5
...

Sheet 顺邮宝挂号
O1: 返 回 目 录
C2: 顺邮宝挂号价目表
C4: (2025/07/07生效)
B6: 国家(地区) | K6: 单价(元/KG) | L6: 处理费(元/件) | M6: 限重(KG)
B7: 英文 | D7: 代码 | E7: 中文
B9: Afghanistan | C9: AF | D9: AF | E9: 阿富汗 | G9: 0 | H9: 2 | K9: 205 | L9: 20 | M9: 2
B10: Albania | C10: AL | D10: AL | E10: 阿尔巴尼亚 | G10: 0 | H10: 2 | K10: 175 | L10: 15 | M10: 2
B11: Algeria | C11: DZ | D11: DZ | E11: 阿尔及利亚 | G11: 0 | H11: 2 | K11: 195 | L11: 14 | M11: 2
B12: American Samoa | C12: AS | D12: AS | E12: 美属萨摩亚 | G12: 0 | H12: 2 | K12: 185 | L12: 20 | M12: 2
B13: Andorra | C13: AD | D13: AD | E13: 安道尔 | G13: 0 | H13: 2 | K13: 305 | L13: 20 | M13: 2
B14: Angola | C14: AO | D14: AO | E14: 安哥拉 | G14: 0 | H14: 2 | K14: 135 | L14: 20 | M14: 2
B15: Anguilla | C15: AI | D15: AI | E15: 安圭拉岛 | G15: 0 | H15: 2 | K15: 485 | L15: 20 | M15: 2
B16: Antigua and Barbuda | C16: AG | D16: AG | E16: 安提瓜和巴布达 | G16: 0 | H16: 2 | K16: 205 | L16: 30 | M16: 2
B17: Argentina | C17: AR | D17: AR | E17: 阿根廷 | G17: 0 | H17: 2 | K17: 255 | L17: 14 | M17: 2
B18: Armenia | C18: AM | D18: AM | E18: 亚美尼亚 | G18: 0 | H18: 2 | K18: 195 | L18: 15 | M18: 2
B19: Aruba | C19: AW | D19: AW | E19: 阿鲁巴 | G19: 0 | H19: 2 | K19: 215 | L19: 37 | M19: 2
B20: Ascension Island | C20: AC | D20: AC | E20: 阿森松岛 | G20: 0 | H20: 2 | K20: 485 | L20: 20 | M20: 2
... B232: Zimbabwe | C232: ZW | D232: ZW | E232: 津巴布韦 | G232: 0 | H232: 2 | K232: 105 | L232: 10 | M232: 2
A235: 地址：深圳市龙华区民治街道光浩国际中心A座19楼 电话：4006075388 网址：www.sypost.com 邮箱：b@sypost.com

Sheet CneForClothes
B1: 路向国 | D1: 包裹处理费 （RMB/票） | E1: 包裹运费 （RMB/KG） | F1: 重量段 （KG） | G1: 重量 min | H1: 重量 max | I1: 参考时效 （工作日） | J1: 旺季参考时效 （工作日） | K1: 包裹运费 （RMB/KG） | L1: 包裹处理费 （RMB/票） | M1: 尺寸限制 （CM） | N1: 备注说明
B2: 美国 | C2: US | D2: 22 | E2: 76 | F2: 0-0.15 | G2: 0 | H2: 0.15 | I2: 7-12 | J2: 10-15 | K2: 105 | L2: 24 | M2: 15＜L≤55，10≤W≤40, H≤25 | N2: 1）起步50g, 2）圆柱体、不规则件，需加收34元/票附加费 3）L≤66且L+2（W+H）≤213cm的超尺寸包裹，需加收34元/票附加费 4）L＞66cm或L+2（W+H）>213cm不可发
B3: 美国 | C3: US | D3: 20 | E3: 76 | F3: 0.151-0.3 | G3: 0 | H3: 0.3 | K3: 98 | L3: 22
B4: 美国 | C4: US | D4: 20 | E4: 76 | F4: 0.301-0.453 | G4: 0.301 | H4: 0.453 | K4: 98 | L4: 18
B5: 美国 | C5: US | D5: 20 | E5: 76 | F5: 0.454-0.7 | G5: 0.454 | H5: 0.7 | K5: 90 | L5: 16
B6: 美国 | C6: US | D6: 16 | E6: 76 | F6: 0.701-1.814 | G6: 0.701 | H6: 1.814 | K6: 86 | L6: 9
B7: 美国 | C7: US | D7: 16 | E7: 79 | F7: 1.815-2 | G7: 1.815 | H7: 2 | K7: 77 | L7: 9
B8: 美国 | C8: US | D8: 12 | E8: 76 | F8: 2.001-10 | G8: 2.001 | H8: 10 | K8: 77 | L8: 9
B9: 英国 | C9: UK/GB | D9: 16 | E9: 50 | F9: 0-0.3 | G9: 0 | H9: 0.3 | I9: 6-9 | J9: 7-10 | K9: 44 | L9: 16 | M9: 15≤L≤60,10≤W≤40，H≤40 | N9: (1)2区禁用,若单独申请开通发货需加收17元/票;​ 2区邮编:苏格兰高地和群岛-邮政编码IV、HS、KA27-28、KW、PA20-49、PA60-78、PH17-26、PH30-44、 PH49-50、马恩岛、根西岛辖区和泽西岛、ZE、GY、JE、IM (2)3区禁用,若单独申请开通发货需加收9元/票​ 3区邮编:北爱尔兰和锡利群岛-邮政编码BT，TR21-25​ 若有需求开通偏远邮编发货,请联系销售经理
B10: 英国 | C10: UK/GB | D10: 16 | E10: 53 | F10: 0.301-1 | G10: 0.301 | H10: 1 | K10: 44 | L10: 16
B11: 英国 | C11: UK/GB | D11: 16 | E11: 53 | F11: 1.001-20 | G11: 1.001 | H11: 20 | K11: 44 | L11: 16
B12: 德国 | C12: DE | D12: 19 | E12: 59 | F12: 0-0.1 | G12: 0 | H12: 0.1 | I12: 6-9 | J12: 7-15 | K12: 52 | L12: 19 | M12: 15≤L≤100,10≤W≤60 | N12: 异形包裹需加收25元/票附加费
B13: 德国 | C13: DE | D13: 19 | E13: 59 | F13: 0.1-0.3 | G13: 0.1 | H13: 0.3 | K13: 52 | L13: 19
B14: 德国 | C14: DE | D14: 22 | E14: 59 | F14: 0.301-30 | G14: 0.301 | H14: 30 | K14: 52 | L14: 21
B15: 意大利 | C15: IT | D15: 24 | E15: 64 | F15: 0-0.3 | G15: 0 | H15: 0.3 | I15: 6-9 | J15: 7-15 | K15: 59 | L15: 24 | M15: 15≤L≤60,10≤W≤50 L+H+W≤130
B16: 意大利 | C16: IT | D16: 23 | E16: 62 | F16: 0.3-5 | G16: 0.3 | H16: 5 | K16: 55 | L16: 23
B17: 西班牙 | C17: ES | D17: 18 | E17: 56 | F17: 0-1 | G17: 0 | H17: 1 | I17: 7-10 | J17: 7-15 | K17: 55 | L17: 18 | M17: 15≤L≤60,10≤W≤50，L+H+W≤150
B18: 西班牙 | C18: ES | D18: 18 | E18: 56 | F18: 1.001-30 | G18: 1.001 | H18: 30 | K18: 50 | L18: 18
B19: 法国 | C19: FR | F19: 0-0.2KG | G19: 0 | H19: 0.2 | I19: 6-9 | J19: 7-12 | K19: 61 | L19: 19 | M19: 15<L≤60,L+W+H≤90 | N19: 禁发圆柱体，异形件加收48元/票
B20: 法国 | C20: FR | F20: 0.201-0.4KG | G20: 0.201 | H20: 0.4 | K20: 61 | L20: 19
B21: 法国 | C21: FR | F21: 0.401-2KG | G21: 0.401 | H21: 2 | K21: 62 | L21: 21
B22: 重要提示： 随着步入旺季，为了尽量保证货物正常转运，请您避免出现以下几种因货物无法上分拣设备需人工操作导致转运延迟的情况： 1.超大规格或小于10x15CM尺寸的货物； 2.不规则货物（例如：球形、三角形、圆柱形等）； 3.面单不合规或模糊褶皱； 4.账户欠费。 5.所有国家不接受亚马逊仓库地址及其他海外仓库地址。
B23: 注意事项：
B24: 一、计泡说明
B25: 1、计泡标准：符合渠道货物类型的按实重计费
B26: 二、在线追踪
B27: 1、专线类挂号小包类可追踪；平邮小包类不可追踪；
B28: 2、查询网址如下：http://www.cne.com；http://www.17track.net
B29: 三、关税相关
B30: 1、清关模式：DDP模式，CNE预收VAT，不提供税单。
B31: 2、美国：不接受申报价值超过USD800的产品，且不接受同一个收件人名且同一地址，当天累计包裹申报价值超过USD800
B32: 3、英国：自2021年1月1日起，所有发往英国的货物取消15GBP以下免征VAT的豁免政策，至此之后申报价值≤135 英镑的 B2C 进口货物需交纳VAT，申报价值＞135 英镑的进口货物需交纳VAT和关税（Duty）。
B33: 4、欧盟国家：下单时若未提供IOSS：（1）与CNE签署代缴协议，由CNE进行VAT的预收和代缴，VAT计费规则是每日发给同一收件人包裹的合计申报价值≤150EUR 时，按照订单申报价值的20%收取；（2）下单时已提供IOSS，申报价值≤150EUR 时，CNE将不再征收VAT；（3）包裹申报价值＞EUR150 时，有无IOSS都要征收VAT，另还会产生关税，产生关税以及产生的关税额度视所寄物品与当地海关的政策法规而定，CNE将会在海关账单下来的当月补扣该费用。
... B56: 特别提示：如贵司同意接受我司服务，即视为贵司已详细阅读过以上内容，并接受各条款的约束。

Sheet CneForGeneral
B1: 路向国 | D1: 包裹处理费 （RMB/票） | E1: 包裹运费 （RMB/KG） | F1: 重量段 （KG） | G1: 重量 min | H1: 重量 max | I1: 参考时效 （工作日） | J1: 旺季参考时效 （工作日） | K1: 包裹运费 （RMB/KG） | L1: 包裹处理费 （RMB/票） | M1: 尺寸限制 （CM） | N1: 备注说明
B2: 美国 | C2: US | D2: 25 | E2: 113 | F2: 0-0.15 | G2: 0 | H2: 0.15 | I2: 7-12 | J2: 10-15 | K2: 113 | L2: 25 | M2: 15＜L≤55，10≤W≤40, H≤25 | N2: 1）起步50g 2）圆柱体、不规则件，需加收34元/票附加费 3）L≤66且L+2（W+H）≤213cm的超尺寸包裹，需加收34元/票附加费 4）L＞66cm或L+2（W+H）>213cm不可发
B3: 美国 | C3: US | D3: 22 | E3: 107 | F3: 0.151-0.3 | G3: 0.151 | H3: 0.3 | K3: 107 | L3: 22
B4: 美国 | C4: US | D4: 20 | E4: 102 | F4: 0.301-0.453 | G4: 0.301 | H4: 0.453 | K4: 102 | L4: 20
B5: 美国 | C5: US | D5: 18 | E5: 96 | F5: 0.454-0.7 | G5: 0.454 | H5: 0.7 | K5: 96 | L5: 18
B6: 美国 | C6: US | D6: 12 | E6: 91 | F6: 0.701-1.814 | G6: 0.701 | H6: 1.814 | K6: 91 | L6: 12
B7: 美国 | C7: US | D7: 12 | E7: 81 | F7: 1.815-2 | G7: 1.815 | H7: 2 | K7: 81 | L7: 12
B8: 美国 | C8: US | D8: 12 | E8: 81 | F8: 2.001-10 | G8: 2.001 | H8: 10 | K8: 81 | L8: 12
B9: 英国 | C9: UK/GB | D9: 16 | E9: 54 | F9: 0-0.3 | G9: 0 | H9: 0.3 | I9: 6-9 | J9: 7-10 | K9: 47 | L9: 16 | M9: 15≤L≤60,10≤W≤40，H≤40 | N9: (1)2区禁用,若单独申请开通发货需加收17元/票;​ 2区邮编:苏格兰高地和群岛-邮政编码IV、HS、KA27-28、KW、PA20-49、PA60-78、PH17-26、PH30-44、 PH49-50、马恩岛、根西岛辖区和泽西岛、ZE、GY、JE、IM (2)3区禁用,若单独申请开通发货需加收9元/票​ 3区邮编:北爱尔兰和锡利群岛-邮政编码BT，TR21-25​ 若有需求开通偏远邮编发货,请联系销售经理
B10: 英国 | C10: UK/GB | D10: 16 | E10: 54 | F10: 0.301-1 | G10: 0.301 | H10: 1 | K10: 47 | L10: 16
B11: 英国 | C11: UK/GB | D11: 16 | E11: 54 | F11: 1.001-30 | G11: 1.001 | H11: 30 | K11: 47 | L11: 16
B12: 法国 | C12: FR | D12: 19 | E12: 73 | F12: 0-0.2 | G12: 0 | H12: 0.2 | I12: 6-9 | J12: 7-12 | K12: 63 | L12: 19 | M12: 15≤L≤80,10≤W≤60 L+W+H≤150 | N12: 禁发圆柱体，异形件加收48元/票
B13: 法国 | C13: FR | D13: 19 | E13: 73 | F13: 0.201-0.4 | G13: 0.201 | H13: 0.4 | K13: 63 | L13: 19
B14: 法国 | C14: FR | D14: 23 | E14: 65 | F14: 0.401-5 | G14: 0.401 | H14: 5 | K14: 64 | L14: 21
B15: 德国 | C15: DE | D15: 19 | E15: 62 | F15: 0-0.3 | G15: 0 | H15: 0.3 | I15: 6-9 | J15: 7-15 | K15: 55 | L15: 19 | M15: 15≤L≤100,10≤W≤60 | N15: 异形包裹需加收25元/票附加费
B16: 德国 | C16: DE | D16: 22 | E16: 62 | F16: 0.3-30 | G16: 0.3 | H16: 30 | K16: 55 | L16: 21
B17: 意大利 | C17: IT | D17: 24 | E17: 72 | F17: 0-0.3 | G17: 0 | H17: 0.3 | I17: 6-9 | J17: 7-15 | K17: 63 | L17: 24 | M17: 15≤L≤60,10≤W≤50 L+H+W≤130
B18: 意大利 | C18: IT | D18: 23 | E18: 70 | F18: 0.301-10 | G18: 0.301 | H18: 10 | K18: 61 | L18: 23
B19: 西班牙 | C19: ES | D19: 18 | E19: 62 | F19: 0-1 | G19: 0 | H19: 1 | I19: 7-10 | J19: 7-15 | K19: 57 | L19: 18 | M19: 15≤L≤60,10≤W≤50，L+H+W≤150
B20: 西班牙 | C20: ES | D20: 18 | E20: 62 | F20: 1.001-30 | G20: 1.001 | H20: 30 | K20: 53 | L20: 18
B21: 爱尔兰 | C21: IE | D21: 23 | E21: 80 | F21: 0-0.2 | G21: 0 | H21: 0.2 | I21: 7-10 | J21: 7-15 | K21: 68 | L21: 23 | M21: 15≤L≤100,10≤W≤50,L+2W+2H≤300
B22: 爱尔兰 | C22: IE | D22: 23 | E22: 70 | F22: 0.201-3 | G22: 0.201 | H22: 3 | K22: 58 | L22: 23
B23: 比利时 | C23: BE | D23: 23 | E23: 75 | F23: 0-0.2 | G23: 0 | H23: 0.2 | I23: 6-9 | J23: 7-15 | K23: 70 | L23: 23 | M23: 15≤L≤100,10≤W≤60 L+H+W<150 | N23: 异形包裹需加收50元/票附加费，直径≥40cm或(直径x2+长)≥2m的异形包裹不可发
B24: 比利时 | C24: BE | D24: 21 | E24: 75 | F24: 0.201-1 | G24: 0.201 | H24: 1 | K24: 66 | L24: 21
B25: 比利时 | C25: BE | D25: 21 | E25: 68 | F25: 1.001-20 | G25: 1.001 | H25: 20 | K25: 59 | L25: 21
B26: 波兰 | C26: PL | D26: 15 | E26: 71 | F26: 0-0.5 | G26: 0 | H26: 0.5 | I26: 6-9 | J26: 7-15 | K26: 72 | L26: 15 | M26: 15≤L≤60,10≤W≤50 | N26: 异形包裹需加收52元/票附加费
B27: 波兰 | C27: PL | D27: 15 | E27: 67 | F27: 0.5-10 | G27: 0.5 | H27: 10 | K27: 57 | L27: 15
B28: 立陶宛 | C28: LT | D28: 21 | E28: 44 | F28: 0-0.3 | G28: 0 | H28: 0.3 | I28: 6-9 | J28: 7-16 | K28: 45 | L28: 21 | M28: 15≤L≤80,10≤W≤60，L+2*W+2*H≤300 | N28: 异形包裹需加收180元/票附加费
B29: 立陶宛 | C29: LT | D29: 21 | E29: 46 | F29: 0.301-0.6 | G29: 0.301 | H29: 0.6 | K29: 51 | L29: 21
B30: 立陶宛 | C30: LT | D30: 21 | E30: 55 | F30: 0.601-20 | G30: 0.601 | H30: 20 | K30: 56 | L30: 21
B31: 匈牙利 | C31: HU | D31: 21 | E31: 59 | F31: 0-1 | G31: 0 | H31: 1 | I31: 6-9 | J31: 7-16 | K31: 64 | L31: 21 | M31: 15≤L≤60,10≤W≤50,H≤30 | N31: 1) 圆柱体、不规则件，且尺寸小于50cm*20cm(直径*高)，需加收55元/票附加费 2) L≤105cm且H≤55cm的超尺寸包裹，附加费55元/票 3) L>105cm或H>55cm不可发
B32: 匈牙利 | C32: HU | D32: 21 | E32: 59 | F32: 45301 | G32: 45301 | H32: 45301 | K32: 64 | L32: 21
B33: 捷克 | C33: CZ | D33: 23 | E33: 70 | F33: 0-1 | G33: 0 | H33: 1 | I33: 6-9 | J33: 7-16 | K33: 70 | L33: 23 | M33: 15≤L≤60,10≤W≤50,H≤30 | N33: 1) 圆柱体、不规则件，且尺寸小于50cm*20cm(直径*高)，需加收55元/票附加费 2) L≤105cm且H≤55cm的超尺寸包裹，附加费55元/票 3) L>105cm或H>55cm不可发
B34: 捷克 | C34: CZ | D34: 23 | E34: 60 | F34: 1.001-10 | G34: 1.001 | H34: 10 | K34: 60 | L34: 23
B35: 荷兰 | C35: NL | D35: 24 | E35: 81 | F35: 0-0.2 | G35: 0 | H35: 0.2 | I35: 6-9 | J35: 7-15 | K35: 82 | L35: 23 | M35: 15≤L≤80,10≤W≤60 | N35: 禁发异形件
B36: 荷兰 | C36: NL | D36: 22 | E36: 71 | F36: 0.201-2 | G36: 0.201 | H36: 2 | K36: 66 | L36: 21
B37: 荷兰 | C37: NL | D37: 22 | E37: 61 | F37: 2-30 | G37: 2 | H37: 30 | K37: 53 | L37: 21
B38: 斯洛伐克 | C38: SK | D38: 21 | E38: 70 | F38: 0-0.2 | G38: 0 | H38: 0.2 | I38: 6-9 | J38: 7-16 | K38: 80 | L38: 22 | M38: 15≤L≤60,10≤W≤50,H≤30 | N38: 1) 圆柱体、不规则件，且尺寸小于50cm*20cm(直径*高)，需加收55元/票附加费 2) L≤105cm且H≤55cm的超尺寸包裹，附加费55元/票 3) L>105cm或H>55cm不可发
B39: 斯洛伐克 | C39: SK | D39: 21 | E39: 70 | F39: 0.2-1 | G39: 0.2 | H39: 1 | K39: 72 | L39: 21
B40: 斯洛伐克 | C40: SK | D40: 21 | E40: 62 | F40: 45321 | G40: 45321 | H40: 45321 | K40: 65 | L40: 21
...

Sheet 4PXForCosmetic
O1: 报价币种：人民币 价格生效日期：2024年10月14日 | P1: 返回目录
A2: 大洲/地区 | B2: 国家/地区 | D2: 产品代码 | E2: 报价区域 | F2: 重量段 （KG） | K2: 收费标准 | M2: 标准尺寸 | N2: 可服务超尺寸及附加费 | O2: 时效 （工作日） | P2: 备注
G3: 重量 min | H3: 重量 max | K3: 运费 RMB/KG | L3: 挂号费 RMB/票
A4: 北美洲 | B4: 美国 | C4: US | D4: S5060 | E4: 华南/华东 | F4: 0-0.1 | G4: 0 | H4: 0.1 | K4: 149 | L4: 49 | M4: 最小尺寸：10*15CM 最大尺寸：三边之和≤90cm，单边≤60cm | N4: / | O4: 15-17 | P4: 可服务邮编，见“分区&无服务邮编表”
B5: 美国 | C5: US | F5: 0.101-0.2 | G5: 0.101 | H5: 0.2 | K5: 161 | L5: 49
B6: 美国 | C6: US | F6: 0.201-0.45 | G6: 0.201 | H6: 0.45 | K6: 165 | L6: 48
B7: 美国 | C7: US | F7: 0.451-0.7 | G7: 0.451 | H7: 0.7 | K7: 165 | L7: 48
B8: 美国 | C8: US | F8: 0.701-1 | G8: 0.701 | H8: 1 | K8: 165 | L8: 39
B9: 美国 | C9: US | F9: 1.001-2 | G9: 1.001 | H9: 2 | K9: 160 | L9: 39
B10: 加拿大 | C10: CA | D10: S5060 | E10: 华南/华东 | F10: 0-0.3 | G10: 0 | H10: 0.3 | K10: 162 | L10: 24 | M10: 最小尺寸：10*15cm 最大尺寸：60cm*40cm*35cm | N10: / | O10: 10-15 | P10: /
B11: 加拿大 | C11: CA | F11: 0.301-0.5 | G11: 0.301 | H11: 0.5 | K11: 162 | L11: 24
B12: 加拿大 | C12: CA | F12: 0.501-2 | G12: 0.501 | H12: 2 | K12: 162 | L12: 24
B13: 加拿大 | C13: CA | F13: 2.001-5 | G13: 2.001 | H13: 5 | K13: 162 | L13: 24
B14: 墨西哥 | C14: MX | D14: S5060 | E14: 华南/华东 | F14: 0-0.5 | G14: 0 | H14: 0.5 | K14: 115 | L14: 21 | M14: 最小尺寸：10*15cm 最大尺寸：40cm*50cm*60cm | N14: / | O14: 10-20 | P14: 可服务邮编，见“分区&无服务邮编表”
B15: 墨西哥 | C15: MX | F15: 0.501-1 | G15: 0.501 | H15: 1 | K15: 115 | L15: 21
B16: 墨西哥 | C16: MX | F16: 1.001-5 | G16: 1.001 | H16: 5 | K16: 115 | L16: 23
A17: 南美洲 | B17: 巴西 | C17: BR | D17: S5060 | E17: 华南/华东 | F17: 0-0.2 | G17: 0 | H17: 0.2 | K17: 90 | L17: 37 | M17: 最小尺寸：10*15cm 最大尺寸：单边长度≤100cm 长+宽+高≤200cm | N17: / | O17: 15-25 受PRC政策影响 预计延误7-10天 | P17: /
B18: 巴西 | C18: BR | F18: 0.201-0.5 | G18: 0.201 | H18: 0.5 | K18: 90 | L18: 37
B19: 巴西 | C19: BR | F19: 0.501-1 | G19: 0.501 | H19: 1 | K19: 90 | L19: 41
B20: 巴西 | C20: BR | F20: 1.01-1.5 | G20: 1.01 | H20: 1.5 | K20: 90 | L20: 49
B21: 巴西 | C21: BR | F21: 1.501-2 | G21: 1.501 | H21: 2 | K21: 90 | L21: 53
B22: 巴西 | C22: BR | F22: 2.01-30 | G22: 2.01 | H22: 30 | K22: 90 | L22: 64
A23: 欧洲 | B23: 法国 | C23: FR | D23: S5060 | E23: 华南/华东 | F23: 0-2 | G23: 0 | H23: 2 | K23: 119 | L23: 23 | M23: 最小尺寸：10CM*15CM 单边尺寸：≤60CM 三边尺寸：长+宽+高≤90CM | N23: / | O23: 10-15 | P23: 无服务邮编：邮编前两位97、98
B24: 德国 | C24: DE | F24: 0-2 | G24: 0 | H24: 2 | K24: 120 | L24: 22 | P24: 无服务邮编：27498、78266
B25: 意大利 | C25: IT | F25: 0-2 | G25: 0 | H25: 2 | K25: 116 | L25: 25 | P25: 无服务邮编：120、47890 – 47899、22061、23030
B26: 西班牙 | C26: ES | F26: 0-2 | G26: 0 | H26: 2 | K26: 135 | L26: 18 | P26: 无服务邮编：51、52、35、38开头、44500、GX11_1AA
B27: 荷兰 | C27: NL | F27: 0-2 | G27: 0 | H27: 2 | K27: 111 | L27: 24
B28: 比利时 | C28: BE | F28: 0-2 | G28: 0 | H28: 2 | K28: 149 | L28: 22
B29: 卢森堡 | C29: LU | F29: 0-2 | G29: 0 | H29: 2 | K29: 133 | L29: 26
B30: 葡萄牙 | C30: PT | F30: 0-2 | G30: 0 | H30: 2 | K30: 139 | L30: 20
B31: 丹麦 | C31: DK | F31: 0-2 | G31: 0 | H31: 2 | K31: 117 | L31: 24 | P31: 无服务邮编：FO 100:999、3900:3999
B32: 克罗地亚 | C32: CRO | F32: 0-2 | G32: 0 | H32: 2 | K32: 115 | L32: 26
B33: 匈牙利 | C33: HU | F33: 0-2 | G33: 0 | H33: 2 | K33: 108 | L33: 21
B34: 塞浦路斯 | C34: CY | F34: 0-2 | G34: 0 | H34: 2 | K34: 115 | L34: 24
B35: 奥地利 | C35: AT | F35: 0-2 | G35: 0 | H35: 2 | K35: 115 | L35: 23
B36: 希腊 | C36: GR | F36: 0-2 | G36: 0 | H36: 2 | K36: 127 | L36: 23 | P36: 无服务邮编：630_86
B37: 拉脱维亚 | C37: LV | F37: 0-2 | G37: 0 | H37: 2 | K37: 108 | L37: 25
B38: 捷克 | C38: CZ | F38: 0-2 | G38: 0 | H38: 2 | K38: 111 | L38: 21
B39: 斯洛伐克 | C39: SK | F39: 0-2 | G39: 0 | H39: 2 | K39: 109 | L39: 21
B40: 斯洛文尼亚 | C40: SI | F40: 0-2 | G40: 0 | H40: 2 | K40: 122 | L40: 26
...

Sheet 4PXForElectric
O1: 报价币种：人民币 价格生效日期：2024年10月19日 | P1: 返回目录
A2: 大洲 | B2: 国家/地区 | D2: 产品代码 | E2: 报价区域 | F2: 重量段 （KG） | K2: 收费标准 | M2: 标准尺寸 | N2: 可服务超尺寸及附加费 | O2: 时效 （工作日） | P2: 备注
G3: 重量 min | H3: 重量 max | K3: 运费 RMB/KG | L3: 挂号费 RMB/票
A4: 北美洲 | B4: 美国 | C4: =VLOOKUP(B4,'[13]Detailed Calculation table'!$A$4:$B$79,2,0) -> US | D4: JW | E4: 华南/华东 | F4: 0-0.1 | G4: 0 | H4: 0.1 | K4: 138 | L4: 20 | M4: 最小尺寸：10*15CM 最大尺寸：60*40*35CM | N4: / | O4: 9-14 | P4: 无服务邮编： ①邮编前3位006-009,967-969,995-999（006-009：波多黎各、维尔京群岛；967-969：夏威夷、关岛；995-999：阿拉斯加）；②不接受APO/FPO军事地址和亚马逊仓库地址；
B5: 美国 | C5: =VLOOKUP(B5,'[13]Detailed Calculation table'!$A$4:$B$79,2,0) -> US | F5: 0.101-0.2 | G5: 0.101 | H5: 0.2 | K5: 133 | L5: 18
B6: 美国 | C6: =VLOOKUP(B6,'[13]Detailed Calculation table'!$A$4:$B$79,2,0) -> US | F6: 0.201-0.45 | G6: 0.201 | H6: 0.45 | K6: 127 | L6: 16
B7: 美国 | C7: =VLOOKUP(B7,'[13]Detailed Calculation table'!$A$4:$B$79,2,0) -> US | F7: 0.451-0.7 | G7: 0.451 | H7: 0.7 | K7: 125 | L7: 16
B8: 美国 | C8: =VLOOKUP(B8,'[13]Detailed Calculation table'!$A$4:$B$79,2,0) -> US | F8: 0.701-1 | G8: 0.701 | H8: 1 | K8: 125 | L8: 9
B9: 美国 | C9: =VLOOKUP(B9,'[13]Detailed Calculation table'!$A$4:$B$79,2,0) -> US | F9: 1.001-3 | G9: 1.001 | H9: 3 | K9: 125 | L9: 9
B10: 美国 | C10: =VLOOKUP(B10,'[13]Detailed Calculation table'!$A$4:$B$79,2,0) -> US | F10: 3.001-6 | G10: 3.001 | H10: 6 | K10: 125 | L10: 9
B11: 美国 | C11: =VLOOKUP(B11,'[13]Detailed Calculation table'!$A$4:$B$79,2,0) -> US | F11: 6.001-30 | G11: 6.001 | H11: 30 | K11: 125 | L11: 9
B12: 加拿大 | C12: =VLOOKUP(B12,'[13]Detailed Calculation table'!$A$4:$B$79,2,0) -> CA | D12: JW | E12: 华南/华东 | F12: 0-0.3 | G12: 0 | H12: 0.3 | K12: 90 | L12: 19 | M12: 单边长度≤100CM 长+宽+高≤200CM | N12: / | O12: 12-17 | P12: /
B13: 加拿大 | C13: =VLOOKUP(B13,'[13]Detailed Calculation table'!$A$4:$B$79,2,0) -> CA | F13: 0.301-0.5 | G13: 0.301 | H13: 0.5 | K13: 90 | L13: 19
B14: 加拿大 | C14: =VLOOKUP(B14,'[13]Detailed Calculation table'!$A$4:$B$79,2,0) -> CA | F14: 0.501-1.5 | G14: 0.501 | H14: 1.5 | K14: 99 | L14: 20
B15: 加拿大 | C15: =VLOOKUP(B15,'[13]Detailed Calculation table'!$A$4:$B$79,2,0) -> CA | F15: 1.501-2 | G15: 1.501 | H15: 2 | K15: 106 | L15: 22
B16: 加拿大 | C16: =VLOOKUP(B16,'[13]Detailed Calculation table'!$A$4:$B$79,2,0) -> CA | F16: 2.001-30 | G16: 2.001 | H16: 30 | K16: 107 | L16: 23
B17: 墨西哥 | C17: =VLOOKUP(B17,'[13]Detailed Calculation table'!$A$4:$B$79,2,0) -> MX | D17: JW | E17: 华南/华东 | F17: 0-0.25 | G17: 0 | H17: 0.25 | K17: 87 | L17: 18 | M17: 最大尺寸：40cm*50m*60cm | N17: / | O17: 12-22 | P17: 【禁运物品清单】
B18: 墨西哥 | C18: =VLOOKUP(B18,'[13]Detailed Calculation table'!$A$4:$B$79,2,0) -> MX | F18: 0.251-0.5 | G18: 0.251 | H18: 0.5 | K18: 87 | L18: 18
B19: 墨西哥 | C19: =VLOOKUP(B19,'[13]Detailed Calculation table'!$A$4:$B$79,2,0) -> MX | F19: 0.501-1 | G19: 0.501 | H19: 1 | K19: 87 | L19: 18
B20: 墨西哥 | C20: =VLOOKUP(B20,'[13]Detailed Calculation table'!$A$4:$B$79,2,0) -> MX | F20: 1.001-1.5 | G20: 1.001 | H20: 1.5 | K20: 94 | L20: 20
B21: 墨西哥 | C21: =VLOOKUP(B21,'[13]Detailed Calculation table'!$A$4:$B$79,2,0) -> MX | F21: 1.501-2 | G21: 1.501 | H21: 2 | K21: 94 | L21: 20
B22: 墨西哥 | C22: =VLOOKUP(B22,'[13]Detailed Calculation table'!$A$4:$B$79,2,0) -> MX | F22: 2.001-10 | G22: 2.001 | H22: 10 | K22: 94 | L22: 20
A23: 欧洲 | B23: 英国 | C23: =VLOOKUP(B23,'[13]Detailed Calculation table'!$A$4:$B$79,2,0) -> UK/GB | D23: JW | E23: 华南/华东 | F23: 0-2 | G23: 0 | H23: 2 | K23: 69 | L23: 16 | M23: 0-2KG： 最小尺寸：10CM*21CM 单边尺寸：≤60CM 三边尺寸：60CM*40CM*35CM 最大体积＜0.04m³ 2-15KG 最小尺寸：10CM*21CM 单边尺寸：≤120CM 三边尺寸：长+宽+高≤150CM 最大体积＜0.04m³ | N23: 主要地区收费标准：130RMB/票； 0-2KG：60CM＜单边≤120CM 或 140CM＜长+宽+高≤150CM或 0-15KG 体积长*宽*高≥0.04m³ 偏远地区：不接受超尺服务 2-15KG不接受超尺服务； | O23: 7-9 | P23: 无服务邮编 详见 【分区&无服务邮编表】
B24: 英国 | C24: =VLOOKUP(B24,'[13]Detailed Calculation table'!$A$4:$B$79,2,0) -> UK/GB | F24: 2.001-15 | G24: 2.001 | H24: 15 | K24: 66 | L24: 16
B25: 德国 | C25: =VLOOKUP(B25,'[13]Detailed Calculation table'!$A$4:$B$79,2,0) -> DE | D25: JW | E25: 华南/华东 | F25: 0-0.3 | G25: 0 | H25: 0.3 | K25: 84 | L25: 19 | M25: 最大尺寸限制：120CM*60CM*60CM；最小尺寸限制：10*21CM | N25: / | O25: 10-12 | P25: 不提供P.O.BOX及军事地址派送服务；
B26: 德国 | C26: =VLOOKUP(B26,'[13]Detailed Calculation table'!$A$4:$B$79,2,0) -> DE | F26: 0.301-2 | G26: 0.301 | H26: 2 | K26: 84 | L26: 22
B27: 德国 | C27: =VLOOKUP(B27,'[13]Detailed Calculation table'!$A$4:$B$79,2,0) -> DE | F27: 2.001-3 | G27: 2.001 | H27: 3 | K27: 84 | L27: 22
